Workbook

Sheet 09 Mars N
A1: SUIVI LOGISTIQUE ET FINANCIER DES APPLICATIONS PAR BAC (V9) | F1: =F44 -> 16113.28
A2: NOMBRE D'HECTARES : | B2: 4 | D2: espèce | E2: Nectarine
A3: DATE D'APPLICATION : | B3: 46090 | D3: N/ Semaine | E3: 1
A5: 👉 RÈGLES DU BAC A : CUVES DU CALCIUM ET ACIDE NITRIQUE
A6: Produit (Menu Déroulant) | B6: Dose / Ha | C6: Dose TOTALE (Auto) | D6: Prix Unitaire | E6: Montant Ligne | F6: Eau Min (L) | G6: Temps (min) | H6: Règle de Sécurité / Note de Terrain
A7: Nitrate de Calcium / نترات كالسـيوم | B7: 3.5 | C7: =IF(A7="","",B7*$B$2) -> 14 | D7: =IF(A7="","",VLOOKUP(A7,Base_Donnees!A:F,6,FALSE)) -> 134.45 | E7: =IF(A7="","",C7*D7) -> 1882.3 | F7: =IF(A7="","",IF(VLOOKUP(A7,Base_Donnees!A:F,3,FALSE)>4000,0,ROUNDUP((C7*1000/VLOOKUP(A7,Base_Donnees!A:F,3,FALSE))*1.5,0))) -> 175 | G7: =IF(A7="","",VLOOKUP(A7,Base_Donnees!A:F,4,FALSE)) -> 6 | H7: =IF(A7="","",VLOOKUP(A7,Base_Donnees!A:F,5,FALSE)) -> CRITIQUE : Isoler totalement des Sulfates/Phosphates.
A8: Acide Nitrique / حامض نيتريك | B8: 2 | C8: =IF(A8="","",B8*$B$2) -> 8 | D8: =IF(A8="","",VLOOKUP(A8,Base_Donnees!A:F,6,FALSE)) -> 378.15 | E8: =IF(A8="","",C8*D8) -> 3025.2 | F8: =IF(A8="","",IF(VLOOKUP(A8,Base_Donnees!A:F,3,FALSE)>4000,0,ROUNDUP((C8*1000/VLOOKUP(A8,Base_Donnees!A:F,3,FALSE))*1.5,0))) -> 0 | G8: =IF(A8="","",VLOOKUP(A8,Base_Donnees!A:F,4,FALSE)) -> 1 | H8: =IF(A8="","",VLOOKUP(A8,Base_Donnees!A:F,5,FALSE)) -> CORROSIF : Gants + lunettes de protection obligatoires.
C9: =IF(A9="","",B9*$B$2) | D9: =IF(A9="","",VLOOKUP(A9,Base_Donnees!A:F,6,FALSE)) | E9: =IF(A9="","",C9*D9) | F9: =IF(A9="","",IF(VLOOKUP(A9,Base_Donnees!A:F,3,FALSE)>4000,0,ROUNDUP((C9*1000/VLOOKUP(A9,Base_Donnees!A:F,3,FALSE))*1.5,0))) | G9: =IF(A9="","",VLOOKUP(A9,Base_Donnees!A:F,4,FALSE)) | H9: =IF(A9="","",VLOOKUP(A9,Base_Donnees!A:F,5,FALSE))
A11: 👉 RÈGLES DU BAC B : CUVE ÉNERGIE & MACRO-ÉLÉMENTS (11 Lignes Disponibles)
A12: Produit (Menu Déroulant) | B12: Dose / Ha | C12: Dose TOTALE (Auto) | D12: Prix Unitaire | E12: Montant Ligne | F12: Eau Min (L) | G12: Temps (min) | H12: Règle de Sécurité / Note de Terrain
A13: Urée / يوريا | B13: 2 | C13: =IF(A13="","",B13*$B$2) -> 8 | D13: =IF(A13="","",VLOOKUP(A13,Base_Donnees!A:F,6,FALSE)) -> 378.15 | E13: =IF(A13="","",C13*D13) -> 3025.2 | F13: =IF(A13="","",IF(VLOOKUP(A13,Base_Donnees!A:F,3,FALSE)>4000,0,ROUNDUP((C13*1000/VLOOKUP(A13,Base_Donnees!A:F,3,FALSE))*1.5,0))) -> 115 | G13: =IF(A13="","",VLOOKUP(A13,Base_Donnees!A:F,4,FALSE)) -> 5 | H13: =IF(A13="","",VLOOKUP(A13,Base_Donnees!A:F,5,FALSE)) -> Très soluble. Refroidit fortement l'eau (endothermique).
A14: Sulfate de Potassium / سلفات البوتاسيوم SOP | B14: 3.5 | C14: =IF(A14="","",B14*$B$2) -> 14 | D14: =IF(A14="","",VLOOKUP(A14,Base_Donnees!A:F,6,FALSE)) -> 168.07 | E14: =IF(A14="","",C14*D14) -> 2352.98 | F14: =IF(A14="","",IF(VLOOKUP(A14,Base_Donnees!A:F,3,FALSE)>4000,0,ROUNDUP((C14*1000/VLOOKUP(A14,Base_Donnees!A:F,3,FALSE))*1.5,0))) -> 2100 | G14: =IF(A14="","",VLOOKUP(A14,Base_Donnees!A:F,4,FALSE)) -> 20 | H14: =IF(A14="","",VLOOKUP(A14,Base_Donnees!A:F,5,FALSE)) -> Le plus difficile à dissoudre du marché. Risque de dépôt.
A15: Sulfate de Magnésium / سلفات ماغنسيوم | B15: 1.5 | C15: =IF(A15="","",B15*$B$2) -> 6 | D15: =IF(A15="","",VLOOKUP(A15,Base_Donnees!A:F,6,FALSE)) -> 201.7 | E15: =IF(A15="","",C15*D15) -> 1210.2 | F15: =IF(A15="","",IF(VLOOKUP(A15,Base_Donnees!A:F,3,FALSE)>4000,0,ROUNDUP((C15*1000/VLOOKUP(A15,Base_Donnees!A:F,3,FALSE))*1.5,0))) -> 360 | G15: =IF(A15="","",VLOOKUP(A15,Base_Donnees!A:F,4,FALSE)) -> 12 | H15: =IF(A15="","",VLOOKUP(A15,Base_Donnees!A:F,5,FALSE)) -> Sel d'Epsom. Parfaitement compatible dans le bloc B.
A16: Acide Phosphorique / حامض فوسفوريك | B16: 2.5 | C16: =IF(A16="","",B16*$B$2) -> 10 | D16: =IF(A16="","",VLOOKUP(A16,Base_Donnees!A:F,6,FALSE)) -> 461.74 | E16: =IF(A16="","",C16*D16) -> 4617.4 | F16: =IF(A16="","",IF(VLOOKUP(A16,Base_Donnees!A:F,3,FALSE)>4000,0,ROUNDUP((C16*1000/VLOOKUP(A16,Base_Donnees!A:F,3,FALSE))*1.5,0))) -> 0 | G16: =IF(A16="","",VLOOKUP(A16,Base_Donnees!A:F,4,FALSE)) -> 1 | H16: =IF(A16="","",VLOOKUP(A16,Base_Donnees!A:F,5,FALSE)) -> Sécurité : Toujours verser l'acide dans l'eau.
C17: =IF(A17="","",B17*$B$2) | D17: =IF(A17="","",VLOOKUP(A17,Base_Donnees!A:F,6,FALSE)) | E17: =IF(A17="","",C17*D17) | F17: =IF(A17="","",IF(VLOOKUP(A17,Base_Donnees!A:F,3,FALSE)>4000,0,ROUNDUP((C17*1000/VLOOKUP(A17,Base_Donnees!A:F,3,FALSE))*1.5,0))) | G17: =IF(A17="","",VLOOKUP(A17,Base_Donnees!A:F,4,FALSE)) | H17: =IF(A17="","",VLOOKUP(A17,Base_Donnees!A:F,5,FALSE))
C18: =IF(A18="","",B18*$B$2) | D18: =IF(A18="","",VLOOKUP(A18,Base_Donnees!A:F,6,FALSE)) | E18: =IF(A18="","",C18*D18) | F18: =IF(A18="","",IF(VLOOKUP(A18,Base_Donnees!A:F,3,FALSE)>4000,0,ROUNDUP((C18*1000/VLOOKUP(A18,Base_Donnees!A:F,3,FALSE))*1.5,0))) | G18: =IF(A18="","",VLOOKUP(A18,Base_Donnees!A:F,4,FALSE)) | H18: =IF(A18="","",VLOOKUP(A18,Base_Donnees!A:F,5,FALSE))
C19: =IF(A19="","",B19*$B$2) | D19: =IF(A19="","",VLOOKUP(A19,Base_Donnees!A:F,6,FALSE)) | E19: =IF(A19="","",C19*D19) | F19: =IF(A19="","",IF(VLOOKUP(A19,Base_Donnees!A:F,3,FALSE)>4000,0,ROUNDUP((C19*1000/VLOOKUP(A19,Base_Donnees!A:F,3,FALSE))*1.5,0))) | G19: =IF(A19="","",VLOOKUP(A19,Base_Donnees!A:F,4,FALSE)) | H19: =IF(A19="","",VLOOKUP(A19,Base_Donnees!A:F,5,FALSE))
C20: =IF(A20="","",B20*$B$2) | D20: =IF(A20="","",VLOOKUP(A20,Base_Donnees!A:F,6,FALSE)) | E20: =IF(A20="","",C20*D20) | F20: =IF(A20="","",IF(VLOOKUP(A20,Base_Donnees!A:F,3,FALSE)>4000,0,ROUNDUP((C20*1000/VLOOKUP(A20,Base_Donnees!A:F,3,FALSE))*1.5,0))) | G20: =IF(A20="","",VLOOKUP(A20,Base_Donnees!A:F,4,FALSE)) | H20: =IF(A20="","",VLOOKUP(A20,Base_Donnees!A:F,5,FALSE))
C21: =IF(A21="","",B21*$B$2) | D21: =IF(A21="","",VLOOKUP(A21,Base_Donnees!A:F,6,FALSE)) | E21: =IF(A21="","",C21*D21) | F21: =IF(A21="","",IF(VLOOKUP(A21,Base_Donnees!A:F,3,FALSE)>4000,0,ROUNDUP((C21*1000/VLOOKUP(A21,Base_Donnees!A:F,3,FALSE))*1.5,0))) | G21: =IF(A21="","",VLOOKUP(A21,Base_Donnees!A:F,4,FALSE)) | H21: =IF(A21="","",VLOOKUP(A21,Base_Donnees!A:F,5,FALSE))
C22: =IF(A22="","",B22*$B$2) | D22: =IF(A22="","",VLOOKUP(A22,Base_Donnees!A:F,6,FALSE)) | E22: =IF(A22="","",C22*D22) | F22: =IF(A22="","",IF(VLOOKUP(A22,Base_Donnees!A:F,3,FALSE)>4000,0,ROUNDUP((C22*1000/VLOOKUP(A22,Base_Donnees!A:F,3,FALSE))*1.5,0))) | G22: =IF(A22="","",VLOOKUP(A22,Base_Donnees!A:F,4,FALSE)) | H22: =IF(A22="","",VLOOKUP(A22,Base_Donnees!A:F,5,FALSE))
C23: =IF(A23="","",B23*$B$2) | D23: =IF(A23="","",VLOOKUP(A23,Base_Donnees!A:F,6,FALSE)) | E23: =IF(A23="","",C23*D23) | F23: =IF(A23="","",IF(VLOOKUP(A23,Base_Donnees!A:F,3,FALSE)>4000,0,ROUNDUP((C23*1000/VLOOKUP(A23,Base_Donnees!A:F,3,FALSE))*1.5,0))) | G23: =IF(A23="","",VLOOKUP(A23,Base_Donnees!A:F,4,FALSE)) | H23: =IF(A23="","",VLOOKUP(A23,Base_Donnees!A:F,5,FALSE))
A25: 👉 RÈGLES DU BAC C : ACIDES DE NETTOYAGE ET OLIGO-ÉLÉMENTS
A26: Produit (Menu Déroulant) | B26: Dose / Ha | C26: Dose TOTALE (Auto) | D26: Prix Unitaire | E26: Montant Ligne | F26: Eau Min (L) | G26: Temps (min) | H26: Règle de Sécurité / Note de Terrain
C27: =IF(A27="","",B27*$B$2) | D27: =IF(A27="","",VLOOKUP(A27,Base_Donnees!A:F,6,FALSE)) | E27: =IF(A27="","",C27*D27) | F27: =IF(A27="","",IF(VLOOKUP(A27,Base_Donnees!A:F,3,FALSE)>4000,0,ROUNDUP((C27*1000/VLOOKUP(A27,Base_Donnees!A:F,3,FALSE))*1.5,0))) | G27: =IF(A27="","",VLOOKUP(A27,Base_Donnees!A:F,4,FALSE)) | H27: =IF(A27="","",VLOOKUP(A27,Base_Donnees!A:F,5,FALSE))
C28: =IF(A28="","",B28*$B$2) | D28: =IF(A28="","",VLOOKUP(A28,Base_Donnees!A:F,6,FALSE)) | E28: =IF(A28="","",C28*D28) | F28: =IF(A28="","",IF(VLOOKUP(A28,Base_Donnees!A:F,3,FALSE)>4000,0,ROUNDUP((C28*1000/VLOOKUP(A28,Base_Donnees!A:F,3,FALSE))*1.5,0))) | G28: =IF(A28="","",VLOOKUP(A28,Base_Donnees!A:F,4,FALSE)) | H28: =IF(A28="","",VLOOKUP(A28,Base_Donnees!A:F,5,FALSE))
C29: =IF(A29="","",B29*$B$2) | D29: =IF(A29="","",VLOOKUP(A29,Base_Donnees!A:F,6,FALSE)) | E29: =IF(A29="","",C29*D29) | F29: =IF(A29="","",IF(VLOOKUP(A29,Base_Donnees!A:F,3,FALSE)>4000,0,ROUNDUP((C29*1000/VLOOKUP(A29,Base_Donnees!A:F,3,FALSE))*1.5,0))) | G29: =IF(A29="","",VLOOKUP(A29,Base_Donnees!A:F,4,FALSE)) | H29: =IF(A29="","",VLOOKUP(A29,Base_Donnees!A:F,5,FALSE))
A31: 👉 RÈGLES DU BAC D (SÉPARÉ) : ACIDE HUMIQUE ET FER CHÉLATÉ
A32: Produit (Menu Déroulant) | B32: Dose / Ha | C32: Dose TOTALE (Auto) | D32: Prix Unitaire | E32: Montant Ligne | F32: Eau Min (L) | G32: Temps (min) | H32: Règle de Sécurité / Note de Terrain
C33: =IF(A33="","",B33*$B$2) | D33: =IF(A33="","",VLOOKUP(A33,Base_Donnees!A:F,6,FALSE)) | E33: =IF(A33="","",C33*D33) | F33: =IF(A33="","",IF(VLOOKUP(A33,Base_Donnees!A:F,3,FALSE)>4000,0,ROUNDUP((C33*1000/VLOOKUP(A33,Base_Donnees!A:F,3,FALSE))*1.5,0))) | G33: =IF(A33="","",VLOOKUP(A33,Base_Donnees!A:F,4,FALSE)) | H33: =IF(A33="","",VLOOKUP(A33,Base_Donnees!A:F,5,FALSE))
C34: =IF(A34="","",B34*$B$2) | D34: =IF(A34="","",VLOOKUP(A34,Base_Donnees!A:F,6,FALSE)) | E34: =IF(A34="","",C34*D34) | F34: =IF(A34="","",IF(VLOOKUP(A34,Base_Donnees!A:F,3,FALSE)>4000,0,ROUNDUP((C34*1000/VLOOKUP(A34,Base_Donnees!A:F,3,FALSE))*1.5,0))) | G34: =IF(A34="","",VLOOKUP(A34,Base_Donnees!A:F,4,FALSE)) | H34: =IF(A34="","",VLOOKUP(A34,Base_Donnees!A:F,5,FALSE))
C35: =IF(A35="","",B35*$B$2) | D35: =IF(A35="","",VLOOKUP(A35,Base_Donnees!A:F,6,FALSE)) | E35: =IF(A35="","",C35*D35) | F35: =IF(A35="","",IF(VLOOKUP(A35,Base_Donnees!A:F,3,FALSE)>4000,0,ROUNDUP((C35*1000/VLOOKUP(A35,Base_Donnees!A:F,3,FALSE))*1.5,0))) | G35: =IF(A35="","",VLOOKUP(A35,Base_Donnees!A:F,4,FALSE)) | H35: =IF(A35="","",VLOOKUP(A35,Base_Donnees!A:F,5,FALSE))
A38: RÉSUMÉ COMPLÈT DE REMPLISSAGE ET COÛTS PAR BAC (RESTAURATION CUVE 1000L)
A39: Identifiant Bac | B39: Eau Initiale à Verser (L) | C39: Vol. Solution Estimé (L) | D39: Alerte Cuve 1000L | E39: Temps Agitation (min) | F39: Coût Total du Bac
A40: BAC A | B40: =SUM(F7:F9) -> 175 | C40: =B40+SUM(C7:C9)*0.6 -> 188.2 | D40: =IF(C40>1000,"TROP PLEIN !","OK") -> OK | E40: =IF(B40=0,0,MAX(G7:G9)) -> 6 | F40: =SUM(E7:E9) -> 4907.5
A41: BAC B | B41: =SUM(F13:F23) -> 2575 | C41: =B41+SUM(C13:C23)*0.6 -> 2597.8 | D41: =IF(C41>1000,"TROP PLEIN !","OK") -> TROP PLEIN ! | E41: =IF(B41=0,0,MAX(G13:G23)) -> 20 | F41: =SUM(E13:E23) -> 11205.78
A42: BAC C | B42: =SUM(F27:F29) -> 0 | C42: =B42+SUM(C27:C29)*0.6 -> 0 | D42: =IF(C42>1000,"TROP PLEIN !","OK") -> OK | E42: =IF(B42=0,0,MAX(G27:G29)) -> 0 | F42: =SUM(E27:E29) -> 0
A43: BAC D (SÉPARÉ) | B43: =SUM(F33:F35) -> 0 | C43: =B43+SUM(C33:C35)*0.6 -> 0 | D43: =IF(C43>1000,"TROP PLEIN !","OK") -> OK | E43: =IF(B43=0,0,MAX(G33:G35)) -> 0 | F43: =SUM(E33:E35) -> 0
F44: =SUM(F40:F43)*E3 -> 16113.28

Sheet 09 Mars P
A1: SUIVI LOGISTIQUE ET FINANCIER DES APPLICATIONS PAR BAC (V9) | F1: =F44 -> 2308.7
A2: NOMBRE D'HECTARES : | B2: 2 | D2: espèce | E2: Pommier
A3: DATE D'APPLICATION : | B3: 46090 | D3: N/ Semaine | E3: 1
A5: 👉 RÈGLES DU BAC A : CUVES DU CALCIUM ET ACIDE NITRIQUE
A6: Produit (Menu Déroulant) | B6: Dose / Ha | C6: Dose TOTALE (Auto) | D6: Prix Unitaire | E6: Montant Ligne | F6: Eau Min (L) | G6: Temps (min) | H6: Règle de Sécurité / Note de Terrain
C7: =IF(A7="","",B7*$B$2) | D7: =IF(A7="","",VLOOKUP(A7,Base_Donnees!A:F,6,FALSE)) | E7: =IF(A7="","",C7*D7) | F7: =IF(A7="","",IF(VLOOKUP(A7,Base_Donnees!A:F,3,FALSE)>4000,0,ROUNDUP((C7*1000/VLOOKUP(A7,Base_Donnees!A:F,3,FALSE))*1.5,0))) | G7: =IF(A7="","",VLOOKUP(A7,Base_Donnees!A:F,4,FALSE)) | H7: =IF(A7="","",VLOOKUP(A7,Base_Donnees!A:F,5,FALSE))
C8: =IF(A8="","",B8*$B$2) | D8: =IF(A8="","",VLOOKUP(A8,Base_Donnees!A:F,6,FALSE)) | E8: =IF(A8="","",C8*D8) | F8: =IF(A8="","",IF(VLOOKUP(A8,Base_Donnees!A:F,3,FALSE)>4000,0,ROUNDUP((C8*1000/VLOOKUP(A8,Base_Donnees!A:F,3,FALSE))*1.5,0))) | G8: =IF(A8="","",VLOOKUP(A8,Base_Donnees!A:F,4,FALSE)) | H8: =IF(A8="","",VLOOKUP(A8,Base_Donnees!A:F,5,FALSE))
C9: =IF(A9="","",B9*$B$2) | D9: =IF(A9="","",VLOOKUP(A9,Base_Donnees!A:F,6,FALSE)) | E9: =IF(A9="","",C9*D9) | F9: =IF(A9="","",IF(VLOOKUP(A9,Base_Donnees!A:F,3,FALSE)>4000,0,ROUNDUP((C9*1000/VLOOKUP(A9,Base_Donnees!A:F,3,FALSE))*1.5,0))) | G9: =IF(A9="","",VLOOKUP(A9,Base_Donnees!A:F,4,FALSE)) | H9: =IF(A9="","",VLOOKUP(A9,Base_Donnees!A:F,5,FALSE))
A11: 👉 RÈGLES DU BAC B : CUVE ÉNERGIE & MACRO-ÉLÉMENTS (11 Lignes Disponibles)
A12: Produit (Menu Déroulant) | B12: Dose / Ha | C12: Dose TOTALE (Auto) | D12: Prix Unitaire | E12: Montant Ligne | F12: Eau Min (L) | G12: Temps (min) | H12: Règle de Sécurité / Note de Terrain
A13: Acide Phosphorique / حامض فوسفوريك | B13: 2.5 | C13: =IF(A13="","",B13*$B$2) -> 5 | D13: =IF(A13="","",VLOOKUP(A13,Base_Donnees!A:F,6,FALSE)) -> 461.74 | E13: =IF(A13="","",C13*D13) -> 2308.7 | F13: =IF(A13="","",IF(VLOOKUP(A13,Base_Donnees!A:F,3,FALSE)>4000,0,ROUNDUP((C13*1000/VLOOKUP(A13,Base_Donnees!A:F,3,FALSE))*1.5,0))) -> 0 | G13: =IF(A13="","",VLOOKUP(A13,Base_Donnees!A:F,4,FALSE)) -> 1 | H13: =IF(A13="","",VLOOKUP(A13,Base_Donnees!A:F,5,FALSE)) -> Sécurité : Toujours verser l'acide dans l'eau.
C14: =IF(A14="","",B14*$B$2) | D14: =IF(A14="","",VLOOKUP(A14,Base_Donnees!A:F,6,FALSE)) | E14: =IF(A14="","",C14*D14) | F14: =IF(A14="","",IF(VLOOKUP(A14,Base_Donnees!A:F,3,FALSE)>4000,0,ROUNDUP((C14*1000/VLOOKUP(A14,Base_Donnees!A:F,3,FALSE))*1.5,0))) | G14: =IF(A14="","",VLOOKUP(A14,Base_Donnees!A:F,4,FALSE)) | H14: =IF(A14="","",VLOOKUP(A14,Base_Donnees!A:F,5,FALSE))
C15: =IF(A15="","",B15*$B$2) | D15: =IF(A15="","",VLOOKUP(A15,Base_Donnees!A:F,6,FALSE)) | E15: =IF(A15="","",C15*D15) | F15: =IF(A15="","",IF(VLOOKUP(A15,Base_Donnees!A:F,3,FALSE)>4000,0,ROUNDUP((C15*1000/VLOOKUP(A15,Base_Donnees!A:F,3,FALSE))*1.5,0))) | G15: =IF(A15="","",VLOOKUP(A15,Base_Donnees!A:F,4,FALSE)) | H15: =IF(A15="","",VLOOKUP(A15,Base_Donnees!A:F,5,FALSE))
C16: =IF(A16="","",B16*$B$2) | D16: =IF(A16="","",VLOOKUP(A16,Base_Donnees!A:F,6,FALSE)) | E16: =IF(A16="","",C16*D16) | F16: =IF(A16="","",IF(VLOOKUP(A16,Base_Donnees!A:F,3,FALSE)>4000,0,ROUNDUP((C16*1000/VLOOKUP(A16,Base_Donnees!A:F,3,FALSE))*1.5,0))) | G16: =IF(A16="","",VLOOKUP(A16,Base_Donnees!A:F,4,FALSE)) | H16: =IF(A16="","",VLOOKUP(A16,Base_Donnees!A:F,5,FALSE))
C17: =IF(A17="","",B17*$B$2) | D17: =IF(A17="","",VLOOKUP(A17,Base_Donnees!A:F,6,FALSE)) | E17: =IF(A17="","",C17*D17) | F17: =IF(A17="","",IF(VLOOKUP(A17,Base_Donnees!A:F,3,FALSE)>4000,0,ROUNDUP((C17*1000/VLOOKUP(A17,Base_Donnees!A:F,3,FALSE))*1.5,0))) | G17: =IF(A17="","",VLOOKUP(A17,Base_Donnees!A:F,4,FALSE)) | H17: =IF(A17="","",VLOOKUP(A17,Base_Donnees!A:F,5,FALSE))
C18: =IF(A18="","",B18*$B$2) | D18: =IF(A18="","",VLOOKUP(A18,Base_Donnees!A:F,6,FALSE)) | E18: =IF(A18="","",C18*D18) | F18: =IF(A18="","",IF(VLOOKUP(A18,Base_Donnees!A:F,3,FALSE)>4000,0,ROUNDUP((C18*1000/VLOOKUP(A18,Base_Donnees!A:F,3,FALSE))*1.5,0))) | G18: =IF(A18="","",VLOOKUP(A18,Base_Donnees!A:F,4,FALSE)) | H18: =IF(A18="","",VLOOKUP(A18,Base_Donnees!A:F,5,FALSE))
C19: =IF(A19="","",B19*$B$2) | D19: =IF(A19="","",VLOOKUP(A19,Base_Donnees!A:F,6,FALSE)) | E19: =IF(A19="","",C19*D19) | F19: =IF(A19="","",IF(VLOOKUP(A19,Base_Donnees!A:F,3,FALSE)>4000,0,ROUNDUP((C19*1000/VLOOKUP(A19,Base_Donnees!A:F,3,FALSE))*1.5,0))) | G19: =IF(A19="","",VLOOKUP(A19,Base_Donnees!A:F,4,FALSE)) | H19: =IF(A19="","",VLOOKUP(A19,Base_Donnees!A:F,5,FALSE))
C20: =IF(A20="","",B20*$B$2) | D20: =IF(A20="","",VLOOKUP(A20,Base_Donnees!A:F,6,FALSE)) | E20: =IF(A20="","",C20*D20) | F20: =IF(A20="","",IF(VLOOKUP(A20,Base_Donnees!A:F,3,FALSE)>4000,0,ROUNDUP((C20*1000/VLOOKUP(A20,Base_Donnees!A:F,3,FALSE))*1.5,0))) | G20: =IF(A20="","",VLOOKUP(A20,Base_Donnees!A:F,4,FALSE)) | H20: =IF(A20="","",VLOOKUP(A20,Base_Donnees!A:F,5,FALSE))
C21: =IF(A21="","",B21*$B$2) | D21: =IF(A21="","",VLOOKUP(A21,Base_Donnees!A:F,6,FALSE)) | E21: =IF(A21="","",C21*D21) | F21: =IF(A21="","",IF(VLOOKUP(A21,Base_Donnees!A:F,3,FALSE)>4000,0,ROUNDUP((C21*1000/VLOOKUP(A21,Base_Donnees!A:F,3,FALSE))*1.5,0))) | G21: =IF(A21="","",VLOOKUP(A21,Base_Donnees!A:F,4,FALSE)) | H21: =IF(A21="","",VLOOKUP(A21,Base_Donnees!A:F,5,FALSE))
C22: =IF(A22="","",B22*$B$2) | D22: =IF(A22="","",VLOOKUP(A22,Base_Donnees!A:F,6,FALSE)) | E22: =IF(A22="","",C22*D22) | F22: =IF(A22="","",IF(VLOOKUP(A22,Base_Donnees!A:F,3,FALSE)>4000,0,ROUNDUP((C22*1000/VLOOKUP(A22,Base_Donnees!A:F,3,FALSE))*1.5,0))) | G22: =IF(A22="","",VLOOKUP(A22,Base_Donnees!A:F,4,FALSE)) | H22: =IF(A22="","",VLOOKUP(A22,Base_Donnees!A:F,5,FALSE))
C23: =IF(A23="","",B23*$B$2) | D23: =IF(A23="","",VLOOKUP(A23,Base_Donnees!A:F,6,FALSE)) | E23: =IF(A23="","",C23*D23) | F23: =IF(A23="","",IF(VLOOKUP(A23,Base_Donnees!A:F,3,FALSE)>4000,0,ROUNDUP((C23*1000/VLOOKUP(A23,Base_Donnees!A:F,3,FALSE))*1.5,0))) | G23: =IF(A23="","",VLOOKUP(A23,Base_Donnees!A:F,4,FALSE)) | H23: =IF(A23="","",VLOOKUP(A23,Base_Donnees!A:F,5,FALSE))
A25: 👉 RÈGLES DU BAC C : ACIDES DE NETTOYAGE ET OLIGO-ÉLÉMENTS
A26: Produit (Menu Déroulant) | B26: Dose / Ha | C26: Dose TOTALE (Auto) | D26: Prix Unitaire | E26: Montant Ligne | F26: Eau Min (L) | G26: Temps (min) | H26: Règle de Sécurité / Note de Terrain
C27: =IF(A27="","",B27*$B$2) | D27: =IF(A27="","",VLOOKUP(A27,Base_Donnees!A:F,6,FALSE)) | E27: =IF(A27="","",C27*D27) | F27: =IF(A27="","",IF(VLOOKUP(A27,Base_Donnees!A:F,3,FALSE)>4000,0,ROUNDUP((C27*1000/VLOOKUP(A27,Base_Donnees!A:F,3,FALSE))*1.5,0))) | G27: =IF(A27="","",VLOOKUP(A27,Base_Donnees!A:F,4,FALSE)) | H27: =IF(A27="","",VLOOKUP(A27,Base_Donnees!A:F,5,FALSE))
C28: =IF(A28="","",B28*$B$2) | D28: =IF(A28="","",VLOOKUP(A28,Base_Donnees!A:F,6,FALSE)) | E28: =IF(A28="","",C28*D28) | F28: =IF(A28="","",IF(VLOOKUP(A28,Base_Donnees!A:F,3,FALSE)>4000,0,ROUNDUP((C28*1000/VLOOKUP(A28,Base_Donnees!A:F,3,FALSE))*1.5,0))) | G28: =IF(A28="","",VLOOKUP(A28,Base_Donnees!A:F,4,FALSE)) | H28: =IF(A28="","",VLOOKUP(A28,Base_Donnees!A:F,5,FALSE))
C29: =IF(A29="","",B29*$B$2) | D29: =IF(A29="","",VLOOKUP(A29,Base_Donnees!A:F,6,FALSE)) | E29: =IF(A29="","",C29*D29) | F29: =IF(A29="","",IF(VLOOKUP(A29,Base_Donnees!A:F,3,FALSE)>4000,0,ROUNDUP((C29*1000/VLOOKUP(A29,Base_Donnees!A:F,3,FALSE))*1.5,0))) | G29: =IF(A29="","",VLOOKUP(A29,Base_Donnees!A:F,4,FALSE)) | H29: =IF(A29="","",VLOOKUP(A29,Base_Donnees!A:F,5,FALSE))
A31: 👉 RÈGLES DU BAC D (SÉPARÉ) : ACIDE HUMIQUE ET FER CHÉLATÉ
A32: Produit (Menu Déroulant) | B32: Dose / Ha | C32: Dose TOTALE (Auto) | D32: Prix Unitaire | E32: Montant Ligne | F32: Eau Min (L) | G32: Temps (min) | H32: Règle de Sécurité / Note de Terrain
C33: =IF(A33="","",B33*$B$2) | D33: =IF(A33="","",VLOOKUP(A33,Base_Donnees!A:F,6,FALSE)) | E33: =IF(A33="","",C33*D33) | F33: =IF(A33="","",IF(VLOOKUP(A33,Base_Donnees!A:F,3,FALSE)>4000,0,ROUNDUP((C33*1000/VLOOKUP(A33,Base_Donnees!A:F,3,FALSE))*1.5,0))) | G33: =IF(A33="","",VLOOKUP(A33,Base_Donnees!A:F,4,FALSE)) | H33: =IF(A33="","",VLOOKUP(A33,Base_Donnees!A:F,5,FALSE))
C34: =IF(A34="","",B34*$B$2) | D34: =IF(A34="","",VLOOKUP(A34,Base_Donnees!A:F,6,FALSE)) | E34: =IF(A34="","",C34*D34) | F34: =IF(A34="","",IF(VLOOKUP(A34,Base_Donnees!A:F,3,FALSE)>4000,0,ROUNDUP((C34*1000/VLOOKUP(A34,Base_Donnees!A:F,3,FALSE))*1.5,0))) | G34: =IF(A34="","",VLOOKUP(A34,Base_Donnees!A:F,4,FALSE)) | H34: =IF(A34="","",VLOOKUP(A34,Base_Donnees!A:F,5,FALSE))
C35: =IF(A35="","",B35*$B$2) | D35: =IF(A35="","",VLOOKUP(A35,Base_Donnees!A:F,6,FALSE)) | E35: =IF(A35="","",C35*D35) | F35: =IF(A35="","",IF(VLOOKUP(A35,Base_Donnees!A:F,3,FALSE)>4000,0,ROUNDUP((C35*1000/VLOOKUP(A35,Base_Donnees!A:F,3,FALSE))*1.5,0))) | G35: =IF(A35="","",VLOOKUP(A35,Base_Donnees!A:F,4,FALSE)) | H35: =IF(A35="","",VLOOKUP(A35,Base_Donnees!A:F,5,FALSE))
A38: RÉSUMÉ COMPLÈT DE REMPLISSAGE ET COÛTS PAR BAC (RESTAURATION CUVE 1000L)
A39: Identifiant Bac | B39: Eau Initiale à Verser (L) | C39: Vol. Solution Estimé (L) | D39: Alerte Cuve 1000L | E39: Temps Agitation (min) | F39: Coût Total du Bac
A40: BAC A | B40: =SUM(F7:F9) -> 0 | C40: =B40+SUM(C7:C9)*0.6 -> 0 | D40: =IF(C40>1000,"TROP PLEIN !","OK") -> OK | E40: =IF(B40=0,0,MAX(G7:G9)) -> 0 | F40: =SUM(E7:E9) -> 0
A41: BAC B | B41: =SUM(F13:F23) -> 0 | C41: =B41+SUM(C13:C23)*0.6 -> 3 | D41: =IF(C41>1000,"TROP PLEIN !","OK") -> OK | E41: =IF(B41=0,0,MAX(G13:G23)) -> 0 | F41: =SUM(E13:E23) -> 2308.7
A42: BAC C | B42: =SUM(F27:F29) -> 0 | C42: =B42+SUM(C27:C29)*0.6 -> 0 | D42: =IF(C42>1000,"TROP PLEIN !","OK") -> OK | E42: =IF(B42=0,0,MAX(G27:G29)) -> 0 | F42: =SUM(E27:E29) -> 0
A43: BAC D (SÉPARÉ) | B43: =SUM(F33:F35) -> 0 | C43: =B43+SUM(C33:C35)*0.6 -> 0 | D43: =IF(C43>1000,"TROP PLEIN !","OK") -> OK | E43: =IF(B43=0,0,MAX(G33:G35)) -> 0 | F43: =SUM(E33:E35) -> 0
F44: =SUM(F40:F43)*E3 -> 2308.7

Sheet 17 Mars O
A1: SUIVI LOGISTIQUE ET FINANCIER DES APPLICATIONS PAR BAC (V9) | F1: =F44 -> 39025.56
A2: NOMBRE D'HECTARES : | B2: 8 | D2: espèce | E2: Olivier
A3: DATE D'APPLICATION : | B3: 46098 | D3: N/ Semaine | E3: 1
A5: 👉 RÈGLES DU BAC A : CUVES DU CALCIUM ET ACIDE NITRIQUE
A6: Produit (Menu Déroulant) | B6: Dose / Ha | C6: Dose TOTALE (Auto) | D6: Prix Unitaire | E6: Montant Ligne | F6: Eau Min (L) | G6: Temps (min) | H6: Règle de Sécurité / Note de Terrain
A7: Nitrate de Calcium / نترات كالسـيوم | B7: 2.5 | C7: =IF(A7="","",B7*$B$2) -> 20 | D7: =IF(A7="","",VLOOKUP(A7,Base_Donnees!A:F,6,FALSE)) -> 134.45 | E7: =IF(A7="","",C7*D7) -> 2689 | F7: =IF(A7="","",IF(VLOOKUP(A7,Base_Donnees!A:F,3,FALSE)>4000,0,ROUNDUP((C7*1000/VLOOKUP(A7,Base_Donnees!A:F,3,FALSE))*1.5,0))) -> 250 | G7: =IF(A7="","",VLOOKUP(A7,Base_Donnees!A:F,4,FALSE)) -> 6 | H7: =IF(A7="","",VLOOKUP(A7,Base_Donnees!A:F,5,FALSE)) -> CRITIQUE : Isoler totalement des Sulfates/Phosphates.
A8: Acide Nitrique / حامض نيتريك | B8: 1.5 | C8: =IF(A8="","",B8*$B$2) -> 12 | D8: =IF(A8="","",VLOOKUP(A8,Base_Donnees!A:F,6,FALSE)) -> 378.15 | E8: =IF(A8="","",C8*D8) -> 4537.8 | F8: =IF(A8="","",IF(VLOOKUP(A8,Base_Donnees!A:F,3,FALSE)>4000,0,ROUNDUP((C8*1000/VLOOKUP(A8,Base_Donnees!A:F,3,FALSE))*1.5,0))) -> 0 | G8: =IF(A8="","",VLOOKUP(A8,Base_Donnees!A:F,4,FALSE)) -> 1 | H8: =IF(A8="","",VLOOKUP(A8,Base_Donnees!A:F,5,FALSE)) -> CORROSIF : Gants + lunettes de protection obligatoires.
C9: =IF(A9="","",B9*$B$2) | D9: =IF(A9="","",VLOOKUP(A9,Base_Donnees!A:F,6,FALSE)) | E9: =IF(A9="","",C9*D9) | F9: =IF(A9="","",IF(VLOOKUP(A9,Base_Donnees!A:F,3,FALSE)>4000,0,ROUNDUP((C9*1000/VLOOKUP(A9,Base_Donnees!A:F,3,FALSE))*1.5,0))) | G9: =IF(A9="","",VLOOKUP(A9,Base_Donnees!A:F,4,FALSE)) | H9: =IF(A9="","",VLOOKUP(A9,Base_Donnees!A:F,5,FALSE))
A11: 👉 RÈGLES DU BAC B : CUVE ÉNERGIE & MACRO-ÉLÉMENTS (11 Lignes Disponibles)
A12: Produit (Menu Déroulant) | B12: Dose / Ha | C12: Dose TOTALE (Auto) | D12: Prix Unitaire | E12: Montant Ligne | F12: Eau Min (L) | G12: Temps (min) | H12: Règle de Sécurité / Note de Terrain
A13: Urée / يوريا | B13: 2 | C13: =IF(A13="","",B13*$B$2) -> 16 | D13: =IF(A13="","",VLOOKUP(A13,Base_Donnees!A:F,6,FALSE)) -> 378.15 | E13: =IF(A13="","",C13*D13) -> 6050.4 | F13: =IF(A13="","",IF(VLOOKUP(A13,Base_Donnees!A:F,3,FALSE)>4000,0,ROUNDUP((C13*1000/VLOOKUP(A13,Base_Donnees!A:F,3,FALSE))*1.5,0))) -> 229 | G13: =IF(A13="","",VLOOKUP(A13,Base_Donnees!A:F,4,FALSE)) -> 5 | H13: =IF(A13="","",VLOOKUP(A13,Base_Donnees!A:F,5,FALSE)) -> Très soluble. Refroidit fortement l'eau (endothermique).
A14: Nitrate de Potassium / نترات البوتاسيوم | B14: 3.5 | C14: =IF(A14="","",B14*$B$2) -> 28 | D14: =IF(A14="","",VLOOKUP(A14,Base_Donnees!A:F,6,FALSE)) -> 218.49 | E14: =IF(A14="","",C14*D14) -> 6117.72 | F14: =IF(A14="","",IF(VLOOKUP(A14,Base_Donnees!A:F,3,FALSE)>4000,0,ROUNDUP((C14*1000/VLOOKUP(A14,Base_Donnees!A:F,3,FALSE))*1.5,0))) -> 1400 | G14: =IF(A14="","",VLOOKUP(A14,Base_Donnees!A:F,4,FALSE)) -> 15 | H14: =IF(A14="","",VLOOKUP(A14,Base_Donnees!A:F,5,FALSE)) -> Sensible à l'eau froide du puits. Agitation requise.
A15: Nitrate de Magnésium / نترات ماغنسيوم | B15: 2 | C15: =IF(A15="","",B15*$B$2) -> 16 | D15: =IF(A15="","",VLOOKUP(A15,Base_Donnees!A:F,6,FALSE)) -> 218.49 | E15: =IF(A15="","",C15*D15) -> 3495.84 | F15: =IF(A15="","",IF(VLOOKUP(A15,Base_Donnees!A:F,3,FALSE)>4000,0,ROUNDUP((C15*1000/VLOOKUP(A15,Base_Donnees!A:F,3,FALSE))*1.5,0))) -> 343 | G15: =IF(A15="","",VLOOKUP(A15,Base_Donnees!A:F,4,FALSE)) -> 8 | H15: =IF(A15="","",VLOOKUP(A15,Base_Donnees!A:F,5,FALSE)) -> Excellente source de magnésium, très soluble.
A16: Acide Phosphorique / حامض فوسفوريك | B16: 2.5 | C16: =IF(A16="","",B16*$B$2) -> 20 | D16: =IF(A16="","",VLOOKUP(A16,Base_Donnees!A:F,6,FALSE)) -> 461.74 | E16: =IF(A16="","",C16*D16) -> 9234.8 | F16: =IF(A16="","",IF(VLOOKUP(A16,Base_Donnees!A:F,3,FALSE)>4000,0,ROUNDUP((C16*1000/VLOOKUP(A16,Base_Donnees!A:F,3,FALSE))*1.5,0))) -> 0 | G16: =IF(A16="","",VLOOKUP(A16,Base_Donnees!A:F,4,FALSE)) -> 1 | H16: =IF(A16="","",VLOOKUP(A16,Base_Donnees!A:F,5,FALSE)) -> Sécurité : Toujours verser l'acide dans l'eau.
C17: =IF(A17="","",B17*$B$2) | D17: =IF(A17="","",VLOOKUP(A17,Base_Donnees!A:F,6,FALSE)) | E17: =IF(A17="","",C17*D17) | F17: =IF(A17="","",IF(VLOOKUP(A17,Base_Donnees!A:F,3,FALSE)>4000,0,ROUNDUP((C17*1000/VLOOKUP(A17,Base_Donnees!A:F,3,FALSE))*1.5,0))) | G17: =IF(A17="","",VLOOKUP(A17,Base_Donnees!A:F,4,FALSE)) | H17: =IF(A17="","",VLOOKUP(A17,Base_Donnees!A:F,5,FALSE))
C18: =IF(A18="","",B18*$B$2) | D18: =IF(A18="","",VLOOKUP(A18,Base_Donnees!A:F,6,FALSE)) | E18: =IF(A18="","",C18*D18) | F18: =IF(A18="","",IF(VLOOKUP(A18,Base_Donnees!A:F,3,FALSE)>4000,0,ROUNDUP((C18*1000/VLOOKUP(A18,Base_Donnees!A:F,3,FALSE))*1.5,0))) | G18: =IF(A18="","",VLOOKUP(A18,Base_Donnees!A:F,4,FALSE)) | H18: =IF(A18="","",VLOOKUP(A18,Base_Donnees!A:F,5,FALSE))
C19: =IF(A19="","",B19*$B$2) | D19: =IF(A19="","",VLOOKUP(A19,Base_Donnees!A:F,6,FALSE)) | E19: =IF(A19="","",C19*D19) | F19: =IF(A19="","",IF(VLOOKUP(A19,Base_Donnees!A:F,3,FALSE)>4000,0,ROUNDUP((C19*1000/VLOOKUP(A19,Base_Donnees!A:F,3,FALSE))*1.5,0))) | G19: =IF(A19="","",VLOOKUP(A19,Base_Donnees!A:F,4,FALSE)) | H19: =IF(A19="","",VLOOKUP(A19,Base_Donnees!A:F,5,FALSE))
C20: =IF(A20="","",B20*$B$2) | D20: =IF(A20="","",VLOOKUP(A20,Base_Donnees!A:F,6,FALSE)) | E20: =IF(A20="","",C20*D20) | F20: =IF(A20="","",IF(VLOOKUP(A20,Base_Donnees!A:F,3,FALSE)>4000,0,ROUNDUP((C20*1000/VLOOKUP(A20,Base_Donnees!A:F,3,FALSE))*1.5,0))) | G20: =IF(A20="","",VLOOKUP(A20,Base_Donnees!A:F,4,FALSE)) | H20: =IF(A20="","",VLOOKUP(A20,Base_Donnees!A:F,5,FALSE))
C21: =IF(A21="","",B21*$B$2) | D21: =IF(A21="","",VLOOKUP(A21,Base_Donnees!A:F,6,FALSE)) | E21: =IF(A21="","",C21*D21) | F21: =IF(A21="","",IF(VLOOKUP(A21,Base_Donnees!A:F,3,FALSE)>4000,0,ROUNDUP((C21*1000/VLOOKUP(A21,Base_Donnees!A:F,3,FALSE))*1.5,0))) | G21: =IF(A21="","",VLOOKUP(A21,Base_Donnees!A:F,4,FALSE)) | H21: =IF(A21="","",VLOOKUP(A21,Base_Donnees!A:F,5,FALSE))
C22: =IF(A22="","",B22*$B$2) | D22: =IF(A22="","",VLOOKUP(A22,Base_Donnees!A:F,6,FALSE)) | E22: =IF(A22="","",C22*D22) | F22: =IF(A22="","",IF(VLOOKUP(A22,Base_Donnees!A:F,3,FALSE)>4000,0,ROUNDUP((C22*1000/VLOOKUP(A22,Base_Donnees!A:F,3,FALSE))*1.5,0))) | G22: =IF(A22="","",VLOOKUP(A22,Base_Donnees!A:F,4,FALSE)) | H22: =IF(A22="","",VLOOKUP(A22,Base_Donnees!A:F,5,FALSE))
C23: =IF(A23="","",B23*$B$2) | D23: =IF(A23="","",VLOOKUP(A23,Base_Donnees!A:F,6,FALSE)) | E23: =IF(A23="","",C23*D23) | F23: =IF(A23="","",IF(VLOOKUP(A23,Base_Donnees!A:F,3,FALSE)>4000,0,ROUNDUP((C23*1000/VLOOKUP(A23,Base_Donnees!A:F,3,FALSE))*1.5,0))) | G23: =IF(A23="","",VLOOKUP(A23,Base_Donnees!A:F,4,FALSE)) | H23: =IF(A23="","",VLOOKUP(A23,Base_Donnees!A:F,5,FALSE))
A25: 👉 RÈGLES DU BAC C : ACIDES DE NETTOYAGE ET OLIGO-ÉLÉMENTS
A26: Produit (Menu Déroulant) | B26: Dose / Ha | C26: Dose TOTALE (Auto) | D26: Prix Unitaire | E26: Montant Ligne | F26: Eau Min (L) | G26: Temps (min) | H26: Règle de Sécurité / Note de Terrain
C27: =IF(A27="","",B27*$B$2) | D27: =IF(A27="","",VLOOKUP(A27,Base_Donnees!A:F,6,FALSE)) | E27: =IF(A27="","",C27*D27) | F27: =IF(A27="","",IF(VLOOKUP(A27,Base_Donnees!A:F,3,FALSE)>4000,0,ROUNDUP((C27*1000/VLOOKUP(A27,Base_Donnees!A:F,3,FALSE))*1.5,0))) | G27: =IF(A27="","",VLOOKUP(A27,Base_Donnees!A:F,4,FALSE)) | H27: =IF(A27="","",VLOOKUP(A27,Base_Donnees!A:F,5,FALSE))
C28: =IF(A28="","",B28*$B$2) | D28: =IF(A28="","",VLOOKUP(A28,Base_Donnees!A:F,6,FALSE)) | E28: =IF(A28="","",C28*D28) | F28: =IF(A28="","",IF(VLOOKUP(A28,Base_Donnees!A:F,3,FALSE)>4000,0,ROUNDUP((C28*1000/VLOOKUP(A28,Base_Donnees!A:F,3,FALSE))*1.5,0))) | G28: =IF(A28="","",VLOOKUP(A28,Base_Donnees!A:F,4,FALSE)) | H28: =IF(A28="","",VLOOKUP(A28,Base_Donnees!A:F,5,FALSE))
C29: =IF(A29="","",B29*$B$2) | D29: =IF(A29="","",VLOOKUP(A29,Base_Donnees!A:F,6,FALSE)) | E29: =IF(A29="","",C29*D29) | F29: =IF(A29="","",IF(VLOOKUP(A29,Base_Donnees!A:F,3,FALSE)>4000,0,ROUNDUP((C29*1000/VLOOKUP(A29,Base_Donnees!A:F,3,FALSE))*1.5,0))) | G29: =IF(A29="","",VLOOKUP(A29,Base_Donnees!A:F,4,FALSE)) | H29: =IF(A29="","",VLOOKUP(A29,Base_Donnees!A:F,5,FALSE))
A31: 👉 RÈGLES DU BAC D (SÉPARÉ) : ACIDE HUMIQUE ET FER CHÉLATÉ
A32: Produit (Menu Déroulant) | B32: Dose / Ha | C32: Dose TOTALE (Auto) | D32: Prix Unitaire | E32: Montant Ligne | F32: Eau Min (L) | G32: Temps (min) | H32: Règle de Sécurité / Note de Terrain
A33: Fer 6% / حديد 6% | B33: 0.25 | C33: =IF(A33="","",B33*$B$2) -> 2 | D33: =IF(A33="","",VLOOKUP(A33,Base_Donnees!A:F,6,FALSE)) -> 3450 | E33: =IF(A33="","",C33*D33) -> 6900 | F33: =IF(A33="","",IF(VLOOKUP(A33,Base_Donnees!A:F,3,FALSE)>4000,0,ROUNDUP((C33*1000/VLOOKUP(A33,Base_Donnees!A:F,3,FALSE))*1.5,0))) -> 25 | G33: =IF(A33="","",VLOOKUP(A33,Base_Donnees!A:F,4,FALSE)) -> 10 | H33: =IF(A33="","",VLOOKUP(A33,Base_Donnees!A:F,5,FALSE)) -> Chélate précieux (EDDHA). Sensible aux UV directs.
C34: =IF(A34="","",B34*$B$2) | D34: =IF(A34="","",VLOOKUP(A34,Base_Donnees!A:F,6,FALSE)) | E34: =IF(A34="","",C34*D34) | F34: =IF(A34="","",IF(VLOOKUP(A34,Base_Donnees!A:F,3,FALSE)>4000,0,ROUNDUP((C34*1000/VLOOKUP(A34,Base_Donnees!A:F,3,FALSE))*1.5,0))) | G34: =IF(A34="","",VLOOKUP(A34,Base_Donnees!A:F,4,FALSE)) | H34: =IF(A34="","",VLOOKUP(A34,Base_Donnees!A:F,5,FALSE))
C35: =IF(A35="","",B35*$B$2) | D35: =IF(A35="","",VLOOKUP(A35,Base_Donnees!A:F,6,FALSE)) | E35: =IF(A35="","",C35*D35) | F35: =IF(A35="","",IF(VLOOKUP(A35,Base_Donnees!A:F,3,FALSE)>4000,0,ROUNDUP((C35*1000/VLOOKUP(A35,Base_Donnees!A:F,3,FALSE))*1.5,0))) | G35: =IF(A35="","",VLOOKUP(A35,Base_Donnees!A:F,4,FALSE)) | H35: =IF(A35="","",VLOOKUP(A35,Base_Donnees!A:F,5,FALSE))
A38: RÉSUMÉ COMPLÈT DE REMPLISSAGE ET COÛTS PAR BAC (RESTAURATION CUVE 1000L)
A39: Identifiant Bac | B39: Eau Initiale à Verser (L) | C39: Vol. Solution Estimé (L) | D39: Alerte Cuve 1000L | E39: Temps Agitation (min) | F39: Coût Total du Bac
A40: BAC A | B40: =SUM(F7:F9) -> 250 | C40: =B40+SUM(C7:C9)*0.6 -> 269.2 | D40: =IF(C40>1000,"TROP PLEIN !","OK") -> OK | E40: =IF(B40=0,0,MAX(G7:G9)) -> 6 | F40: =SUM(E7:E9) -> 7226.8
A41: BAC B | B41: =SUM(F13:F23) -> 1972 | C41: =B41+SUM(C13:C23)*0.6 -> 2020 | D41: =IF(C41>1000,"TROP PLEIN !","OK") -> TROP PLEIN ! | E41: =IF(B41=0,0,MAX(G13:G23)) -> 15 | F41: =SUM(E13:E23) -> 24898.76
A42: BAC C | B42: =SUM(F27:F29) -> 0 | C42: =B42+SUM(C27:C29)*0.6 -> 0 | D42: =IF(C42>1000,"TROP PLEIN !","OK") -> OK | E42: =IF(B42=0,0,MAX(G27:G29)) -> 0 | F42: =SUM(E27:E29) -> 0
A43: BAC D (SÉPARÉ) | B43: =SUM(F33:F35) -> 25 | C43: =B43+SUM(C33:C35)*0.6 -> 26.2 | D43: =IF(C43>1000,"TROP PLEIN !","OK") -> OK | E43: =IF(B43=0,0,MAX(G33:G35)) -> 10 | F43: =SUM(E33:E35) -> 6900
F44: =SUM(F40:F43)*E3 -> 39025.56

Sheet Modèle_A_Dupliquer
A1: SUIVI LOGISTIQUE ET FINANCIER DES APPLICATIONS PAR BAC (V9) | F1: =F44 -> 11494.28
A2: NOMBRE D'HECTARES : | B2: 4
A3: DATE D'APPLICATION : | B3: 46159
A5: 👉 RÈGLES DU BAC A : CUVES DU CALCIUM ET ACIDE NITRIQUE
A6: Produit (Menu Déroulant) | B6: Dose / Ha | C6: Dose TOTALE (Auto) | D6: Prix Unitaire | E6: Montant Ligne | F6: Eau Min (L) | G6: Temps (min) | H6: Règle de Sécurité / Note de Terrain
A7: Acide Nitrique / حامض نيتريك | B7: 1 | C7: =IF(A7="","",B7*$B$2) -> 4 | D7: =IF(A7="","",VLOOKUP(A7,Base_Donnees!A:F,6,FALSE)) -> 378.15 | E7: =IF(A7="","",C7*D7) -> 1512.6 | F7: =IF(A7="","",IF(VLOOKUP(A7,Base_Donnees!A:F,3,FALSE)>4000,0,ROUNDUP((C7*1000/VLOOKUP(A7,Base_Donnees!A:F,3,FALSE))*1.5,0))) -> 0 | G7: =IF(A7="","",VLOOKUP(A7,Base_Donnees!A:F,4,FALSE)) -> 1 | H7: =IF(A7="","",VLOOKUP(A7,Base_Donnees!A:F,5,FALSE)) -> CORROSIF : Gants + lunettes de protection obligatoires. | J7: الزيتون
C8: =IF(A8="","",B8*$B$2) | D8: =IF(A8="","",VLOOKUP(A8,Base_Donnees!A:F,6,FALSE)) | E8: =IF(A8="","",C8*D8) | F8: =IF(A8="","",IF(VLOOKUP(A8,Base_Donnees!A:F,3,FALSE)>4000,0,ROUNDUP((C8*1000/VLOOKUP(A8,Base_Donnees!A:F,3,FALSE))*1.5,0))) | G8: =IF(A8="","",VLOOKUP(A8,Base_Donnees!A:F,4,FALSE)) | H8: =IF(A8="","",VLOOKUP(A8,Base_Donnees!A:F,5,FALSE)) | J8: نترات بوتاسيوم 7 ك
C9: =IF(A9="","",B9*$B$2) | D9: =IF(A9="","",VLOOKUP(A9,Base_Donnees!A:F,6,FALSE)) | E9: =IF(A9="","",C9*D9) | F9: =IF(A9="","",IF(VLOOKUP(A9,Base_Donnees!A:F,3,FALSE)>4000,0,ROUNDUP((C9*1000/VLOOKUP(A9,Base_Donnees!A:F,3,FALSE))*1.5,0))) | G9: =IF(A9="","",VLOOKUP(A9,Base_Donnees!A:F,4,FALSE)) | H9: =IF(A9="","",VLOOKUP(A9,Base_Donnees!A:F,5,FALSE)) | J9: نترات ماغنسيوم 2.5
J10: حامض فوسفوريك 1
A11: 👉 RÈGLES DU BAC B : CUVE ÉNERGIE & MACRO-ÉLÉMENTS (11 Lignes Disponibles) | J11: نيتريك ١ لتر
A12: Produit (Menu Déroulant) | B12: Dose / Ha | C12: Dose TOTALE (Auto) | D12: Prix Unitaire | E12: Montant Ligne | F12: Eau Min (L) | G12: Temps (min) | H12: Règle de Sécurité / Note de Terrain | J12: ٣ مرات
A13: Nitrate de Potassium / نترات البوتاسيوم | B13: 7 | C13: =IF(A13="","",B13*$B$2) -> 28 | D13: =IF(A13="","",VLOOKUP(A13,Base_Donnees!A:F,6,FALSE)) -> 218.49 | E13: =IF(A13="","",C13*D13) -> 6117.72 | F13: =IF(A13="","",IF(VLOOKUP(A13,Base_Donnees!A:F,3,FALSE)>4000,0,ROUNDUP((C13*1000/VLOOKUP(A13,Base_Donnees!A:F,3,FALSE))*1.5,0))) -> 1400 | G13: =IF(A13="","",VLOOKUP(A13,Base_Donnees!A:F,4,FALSE)) -> 15 | H13: =IF(A13="","",VLOOKUP(A13,Base_Donnees!A:F,5,FALSE)) -> Sensible à l'eau froide du puits. Agitation requise. | J13: ……
A14: Sulfate de Magnésium / سلفات ماغنسيوم | B14: 2.5 | C14: =IF(A14="","",B14*$B$2) -> 10 | D14: =IF(A14="","",VLOOKUP(A14,Base_Donnees!A:F,6,FALSE)) -> 201.7 | E14: =IF(A14="","",C14*D14) -> 2017 | F14: =IF(A14="","",IF(VLOOKUP(A14,Base_Donnees!A:F,3,FALSE)>4000,0,ROUNDUP((C14*1000/VLOOKUP(A14,Base_Donnees!A:F,3,FALSE))*1.5,0))) -> 600 | G14: =IF(A14="","",VLOOKUP(A14,Base_Donnees!A:F,4,FALSE)) -> 12 | H14: =IF(A14="","",VLOOKUP(A14,Base_Donnees!A:F,5,FALSE)) -> Sel d'Epsom. Parfaitement compatible dans le bloc B. | J14: نترات كالسيوم 3.5 كيلو
A15: Acide Phosphorique / حامض فوسفوريك | B15: 1 | C15: =IF(A15="","",B15*$B$2) -> 4 | D15: =IF(A15="","",VLOOKUP(A15,Base_Donnees!A:F,6,FALSE)) -> 461.74 | E15: =IF(A15="","",C15*D15) -> 1846.96 | F15: =IF(A15="","",IF(VLOOKUP(A15,Base_Donnees!A:F,3,FALSE)>4000,0,ROUNDUP((C15*1000/VLOOKUP(A15,Base_Donnees!A:F,3,FALSE))*1.5,0))) -> 0 | G15: =IF(A15="","",VLOOKUP(A15,Base_Donnees!A:F,4,FALSE)) -> 1 | H15: =IF(A15="","",VLOOKUP(A15,Base_Donnees!A:F,5,FALSE)) -> Sécurité : Toujours verser l'acide dans l'eau. | J15: سيتريك اسيد 2
C16: =IF(A16="","",B16*$B$2) | D16: =IF(A16="","",VLOOKUP(A16,Base_Donnees!A:F,6,FALSE)) | E16: =IF(A16="","",C16*D16) | F16: =IF(A16="","",IF(VLOOKUP(A16,Base_Donnees!A:F,3,FALSE)>4000,0,ROUNDUP((C16*1000/VLOOKUP(A16,Base_Donnees!A:F,3,FALSE))*1.5,0))) | G16: =IF(A16="","",VLOOKUP(A16,Base_Donnees!A:F,4,FALSE)) | H16: =IF(A16="","",VLOOKUP(A16,Base_Donnees!A:F,5,FALSE)) | J16: أسكوربيك اسيد 1 ك
C17: =IF(A17="","",B17*$B$2) | D17: =IF(A17="","",VLOOKUP(A17,Base_Donnees!A:F,6,FALSE)) | E17: =IF(A17="","",C17*D17) | F17: =IF(A17="","",IF(VLOOKUP(A17,Base_Donnees!A:F,3,FALSE)>4000,0,ROUNDUP((C17*1000/VLOOKUP(A17,Base_Donnees!A:F,3,FALSE))*1.5,0))) | G17: =IF(A17="","",VLOOKUP(A17,Base_Donnees!A:F,4,FALSE)) | H17: =IF(A17="","",VLOOKUP(A17,Base_Donnees!A:F,5,FALSE)) | J17: مرة في الاسبوع
C18: =IF(A18="","",B18*$B$2) | D18: =IF(A18="","",VLOOKUP(A18,Base_Donnees!A:F,6,FALSE)) | E18: =IF(A18="","",C18*D18) | F18: =IF(A18="","",IF(VLOOKUP(A18,Base_Donnees!A:F,3,FALSE)>4000,0,ROUNDUP((C18*1000/VLOOKUP(A18,Base_Donnees!A:F,3,FALSE))*1.5,0))) | G18: =IF(A18="","",VLOOKUP(A18,Base_Donnees!A:F,4,FALSE)) | H18: =IF(A18="","",VLOOKUP(A18,Base_Donnees!A:F,5,FALSE))
C19: =IF(A19="","",B19*$B$2) | D19: =IF(A19="","",VLOOKUP(A19,Base_Donnees!A:F,6,FALSE)) | E19: =IF(A19="","",C19*D19) | F19: =IF(A19="","",IF(VLOOKUP(A19,Base_Donnees!A:F,3,FALSE)>4000,0,ROUNDUP((C19*1000/VLOOKUP(A19,Base_Donnees!A:F,3,FALSE))*1.5,0))) | G19: =IF(A19="","",VLOOKUP(A19,Base_Donnees!A:F,4,FALSE)) | H19: =IF(A19="","",VLOOKUP(A19,Base_Donnees!A:F,5,FALSE))
C20: =IF(A20="","",B20*$B$2) | D20: =IF(A20="","",VLOOKUP(A20,Base_Donnees!A:F,6,FALSE)) | E20: =IF(A20="","",C20*D20) | F20: =IF(A20="","",IF(VLOOKUP(A20,Base_Donnees!A:F,3,FALSE)>4000,0,ROUNDUP((C20*1000/VLOOKUP(A20,Base_Donnees!A:F,3,FALSE))*1.5,0))) | G20: =IF(A20="","",VLOOKUP(A20,Base_Donnees!A:F,4,FALSE)) | H20: =IF(A20="","",VLOOKUP(A20,Base_Donnees!A:F,5,FALSE))
C21: =IF(A21="","",B21*$B$2) | D21: =IF(A21="","",VLOOKUP(A21,Base_Donnees!A:F,6,FALSE)) | E21: =IF(A21="","",C21*D21) | F21: =IF(A21="","",IF(VLOOKUP(A21,Base_Donnees!A:F,3,FALSE)>4000,0,ROUNDUP((C21*1000/VLOOKUP(A21,Base_Donnees!A:F,3,FALSE))*1.5,0))) | G21: =IF(A21="","",VLOOKUP(A21,Base_Donnees!A:F,4,FALSE)) | H21: =IF(A21="","",VLOOKUP(A21,Base_Donnees!A:F,5,FALSE))
C22: =IF(A22="","",B22*$B$2) | D22: =IF(A22="","",VLOOKUP(A22,Base_Donnees!A:F,6,FALSE)) | E22: =IF(A22="","",C22*D22) | F22: =IF(A22="","",IF(VLOOKUP(A22,Base_Donnees!A:F,3,FALSE)>4000,0,ROUNDUP((C22*1000/VLOOKUP(A22,Base_Donnees!A:F,3,FALSE))*1.5,0))) | G22: =IF(A22="","",VLOOKUP(A22,Base_Donnees!A:F,4,FALSE)) | H22: =IF(A22="","",VLOOKUP(A22,Base_Donnees!A:F,5,FALSE))
C23: =IF(A23="","",B23*$B$2) | D23: =IF(A23="","",VLOOKUP(A23,Base_Donnees!A:F,6,FALSE)) | E23: =IF(A23="","",C23*D23) | F23: =IF(A23="","",IF(VLOOKUP(A23,Base_Donnees!A:F,3,FALSE)>4000,0,ROUNDUP((C23*1000/VLOOKUP(A23,Base_Donnees!A:F,3,FALSE))*1.5,0))) | G23: =IF(A23="","",VLOOKUP(A23,Base_Donnees!A:F,4,FALSE)) | H23: =IF(A23="","",VLOOKUP(A23,Base_Donnees!A:F,5,FALSE))
A25: 👉 RÈGLES DU BAC C : ACIDES DE NETTOYAGE ET OLIGO-ÉLÉMENTS
A26: Produit (Menu Déroulant) | B26: Dose / Ha | C26: Dose TOTALE (Auto) | D26: Prix Unitaire | E26: Montant Ligne | F26: Eau Min (L) | G26: Temps (min) | H26: Règle de Sécurité / Note de Terrain
C27: =IF(A27="","",B27*$B$2) | D27: =IF(A27="","",VLOOKUP(A27,Base_Donnees!A:F,6,FALSE)) | E27: =IF(A27="","",C27*D27) | F27: =IF(A27="","",IF(VLOOKUP(A27,Base_Donnees!A:F,3,FALSE)>4000,0,ROUNDUP((C27*1000/VLOOKUP(A27,Base_Donnees!A:F,3,FALSE))*1.5,0))) | G27: =IF(A27="","",VLOOKUP(A27,Base_Donnees!A:F,4,FALSE)) | H27: =IF(A27="","",VLOOKUP(A27,Base_Donnees!A:F,5,FALSE))
C28: =IF(A28="","",B28*$B$2) | D28: =IF(A28="","",VLOOKUP(A28,Base_Donnees!A:F,6,FALSE)) | E28: =IF(A28="","",C28*D28) | F28: =IF(A28="","",IF(VLOOKUP(A28,Base_Donnees!A:F,3,FALSE)>4000,0,ROUNDUP((C28*1000/VLOOKUP(A28,Base_Donnees!A:F,3,FALSE))*1.5,0))) | G28: =IF(A28="","",VLOOKUP(A28,Base_Donnees!A:F,4,FALSE)) | H28: =IF(A28="","",VLOOKUP(A28,Base_Donnees!A:F,5,FALSE))
C29: =IF(A29="","",B29*$B$2) | D29: =IF(A29="","",VLOOKUP(A29,Base_Donnees!A:F,6,FALSE)) | E29: =IF(A29="","",C29*D29) | F29: =IF(A29="","",IF(VLOOKUP(A29,Base_Donnees!A:F,3,FALSE)>4000,0,ROUNDUP((C29*1000/VLOOKUP(A29,Base_Donnees!A:F,3,FALSE))*1.5,0))) | G29: =IF(A29="","",VLOOKUP(A29,Base_Donnees!A:F,4,FALSE)) | H29: =IF(A29="","",VLOOKUP(A29,Base_Donnees!A:F,5,FALSE))
A31: 👉 RÈGLES DU BAC D (SÉPARÉ) : ACIDE HUMIQUE ET FER CHÉLATÉ
A32: Produit (Menu Déroulant) | B32: Dose / Ha | C32: Dose TOTALE (Auto) | D32: Prix Unitaire | E32: Montant Ligne | F32: Eau Min (L) | G32: Temps (min) | H32: Règle de Sécurité / Note de Terrain
C33: =IF(A33="","",B33*$B$2) | D33: =IF(A33="","",VLOOKUP(A33,Base_Donnees!A:F,6,FALSE)) | E33: =IF(A33="","",C33*D33) | F33: =IF(A33="","",IF(VLOOKUP(A33,Base_Donnees!A:F,3,FALSE)>4000,0,ROUNDUP((C33*1000/VLOOKUP(A33,Base_Donnees!A:F,3,FALSE))*1.5,0))) | G33: =IF(A33="","",VLOOKUP(A33,Base_Donnees!A:F,4,FALSE)) | H33: =IF(A33="","",VLOOKUP(A33,Base_Donnees!A:F,5,FALSE))
C34: =IF(A34="","",B34*$B$2) | D34: =IF(A34="","",VLOOKUP(A34,Base_Donnees!A:F,6,FALSE)) | E34: =IF(A34="","",C34*D34) | F34: =IF(A34="","",IF(VLOOKUP(A34,Base_Donnees!A:F,3,FALSE)>4000,0,ROUNDUP((C34*1000/VLOOKUP(A34,Base_Donnees!A:F,3,FALSE))*1.5,0))) | G34: =IF(A34="","",VLOOKUP(A34,Base_Donnees!A:F,4,FALSE)) | H34: =IF(A34="","",VLOOKUP(A34,Base_Donnees!A:F,5,FALSE))
C35: =IF(A35="","",B35*$B$2) | D35: =IF(A35="","",VLOOKUP(A35,Base_Donnees!A:F,6,FALSE)) | E35: =IF(A35="","",C35*D35) | F35: =IF(A35="","",IF(VLOOKUP(A35,Base_Donnees!A:F,3,FALSE)>4000,0,ROUNDUP((C35*1000/VLOOKUP(A35,Base_Donnees!A:F,3,FALSE))*1.5,0))) | G35: =IF(A35="","",VLOOKUP(A35,Base_Donnees!A:F,4,FALSE)) | H35: =IF(A35="","",VLOOKUP(A35,Base_Donnees!A:F,5,FALSE))
A38: RÉSUMÉ COMPLÈT DE REMPLISSAGE ET COÛTS PAR BAC (RESTAURATION CUVE 1000L)
A39: Identifiant Bac | B39: Eau Initiale à Verser (L) | C39: Vol. Solution Estimé (L) | D39: Alerte Cuve 1000L | E39: Temps Agitation (min) | F39: Coût Total du Bac
A40: BAC A | B40: =SUM(F7:F9) -> 0 | C40: =B40+SUM(C7:C9)*0.6 -> 2.4 | D40: =IF(C40>1000,"TROP PLEIN !","OK") -> OK | E40: =IF(B40=0,0,MAX(G7:G9)) -> 0 | F40: =SUM(E7:E9) -> 1512.6
A41: BAC B | B41: =SUM(F13:F23) -> 2000 | C41: =B41+SUM(C13:C23)*0.6 -> 2025.2 | D41: =IF(C41>1000,"TROP PLEIN !","OK") -> TROP PLEIN ! | E41: =IF(B41=0,0,MAX(G13:G23)) -> 15 | F41: =SUM(E13:E23) -> 9981.68
A42: BAC C | B42: =SUM(F27:F29) -> 0 | C42: =B42+SUM(C27:C29)*0.6 -> 0 | D42: =IF(C42>1000,"TROP PLEIN !","OK") -> OK | E42: =IF(B42=0,0,MAX(G27:G29)) -> 0 | F42: =SUM(E27:E29) -> 0
A43: BAC D (SÉPARÉ) | B43: =SUM(F33:F35) -> 0 | C43: =B43+SUM(C33:C35)*0.6 -> 0 | D43: =IF(C43>1000,"TROP PLEIN !","OK") -> OK | E43: =IF(B43=0,0,MAX(G33:G35)) -> 0 | F43: =SUM(E33:E35) -> 0
F44: =SUM(F40:F43) -> 11494.28

Sheet Modèle_A_Dupliquer (2)
A1: SUIVI LOGISTIQUE ET FINANCIER DES APPLICATIONS PAR BAC (V9) | F1: =F44 -> 0
A2: NOMBRE D'HECTARES : | B2: 1
A3: DATE D'APPLICATION : | B3: 46159
A5: 👉 RÈGLES DU BAC A : CUVES DU CALCIUM ET ACIDE NITRIQUE
A6: Produit (Menu Déroulant) | B6: Dose / Ha | C6: Dose TOTALE (Auto) | D6: Prix Unitaire | E6: Montant Ligne | F6: Eau Min (L) | G6: Temps (min) | H6: Règle de Sécurité / Note de Terrain
C7: =IF(A7="","",B7*$B$2) | D7: =IF(A7="","",VLOOKUP(A7,Base_Donnees!A:F,6,FALSE)) | E7: =IF(A7="","",C7*D7) | F7: =IF(A7="","",IF(VLOOKUP(A7,Base_Donnees!A:F,3,FALSE)>4000,0,ROUNDUP((C7*1000/VLOOKUP(A7,Base_Donnees!A:F,3,FALSE))*1.5,0))) | G7: =IF(A7="","",VLOOKUP(A7,Base_Donnees!A:F,4,FALSE)) | H7: =IF(A7="","",VLOOKUP(A7,Base_Donnees!A:F,5,FALSE))
C8: =IF(A8="","",B8*$B$2) | D8: =IF(A8="","",VLOOKUP(A8,Base_Donnees!A:F,6,FALSE)) | E8: =IF(A8="","",C8*D8) | F8: =IF(A8="","",IF(VLOOKUP(A8,Base_Donnees!A:F,3,FALSE)>4000,0,ROUNDUP((C8*1000/VLOOKUP(A8,Base_Donnees!A:F,3,FALSE))*1.5,0))) | G8: =IF(A8="","",VLOOKUP(A8,Base_Donnees!A:F,4,FALSE)) | H8: =IF(A8="","",VLOOKUP(A8,Base_Donnees!A:F,5,FALSE))
C9: =IF(A9="","",B9*$B$2) | D9: =IF(A9="","",VLOOKUP(A9,Base_Donnees!A:F,6,FALSE)) | E9: =IF(A9="","",C9*D9) | F9: =IF(A9="","",IF(VLOOKUP(A9,Base_Donnees!A:F,3,FALSE)>4000,0,ROUNDUP((C9*1000/VLOOKUP(A9,Base_Donnees!A:F,3,FALSE))*1.5,0))) | G9: =IF(A9="","",VLOOKUP(A9,Base_Donnees!A:F,4,FALSE)) | H9: =IF(A9="","",VLOOKUP(A9,Base_Donnees!A:F,5,FALSE))
A11: 👉 RÈGLES DU BAC B : CUVE ÉNERGIE & MACRO-ÉLÉMENTS (11 Lignes Disponibles)
A12: Produit (Menu Déroulant) | B12: Dose / Ha | C12: Dose TOTALE (Auto) | D12: Prix Unitaire | E12: Montant Ligne | F12: Eau Min (L) | G12: Temps (min) | H12: Règle de Sécurité / Note de Terrain
C13: =IF(A13="","",B13*$B$2) | D13: =IF(A13="","",VLOOKUP(A13,Base_Donnees!A:F,6,FALSE)) | E13: =IF(A13="","",C13*D13) | F13: =IF(A13="","",IF(VLOOKUP(A13,Base_Donnees!A:F,3,FALSE)>4000,0,ROUNDUP((C13*1000/VLOOKUP(A13,Base_Donnees!A:F,3,FALSE))*1.5,0))) | G13: =IF(A13="","",VLOOKUP(A13,Base_Donnees!A:F,4,FALSE)) | H13: =IF(A13="","",VLOOKUP(A13,Base_Donnees!A:F,5,FALSE))
C14: =IF(A14="","",B14*$B$2) | D14: =IF(A14="","",VLOOKUP(A14,Base_Donnees!A:F,6,FALSE)) | E14: =IF(A14="","",C14*D14) | F14: =IF(A14="","",IF(VLOOKUP(A14,Base_Donnees!A:F,3,FALSE)>4000,0,ROUNDUP((C14*1000/VLOOKUP(A14,Base_Donnees!A:F,3,FALSE))*1.5,0))) | G14: =IF(A14="","",VLOOKUP(A14,Base_Donnees!A:F,4,FALSE)) | H14: =IF(A14="","",VLOOKUP(A14,Base_Donnees!A:F,5,FALSE))
C15: =IF(A15="","",B15*$B$2) | D15: =IF(A15="","",VLOOKUP(A15,Base_Donnees!A:F,6,FALSE)) | E15: =IF(A15="","",C15*D15) | F15: =IF(A15="","",IF(VLOOKUP(A15,Base_Donnees!A:F,3,FALSE)>4000,0,ROUNDUP((C15*1000/VLOOKUP(A15,Base_Donnees!A:F,3,FALSE))*1.5,0))) | G15: =IF(A15="","",VLOOKUP(A15,Base_Donnees!A:F,4,FALSE)) | H15: =IF(A15="","",VLOOKUP(A15,Base_Donnees!A:F,5,FALSE))
C16: =IF(A16="","",B16*$B$2) | D16: =IF(A16="","",VLOOKUP(A16,Base_Donnees!A:F,6,FALSE)) | E16: =IF(A16="","",C16*D16) | F16: =IF(A16="","",IF(VLOOKUP(A16,Base_Donnees!A:F,3,FALSE)>4000,0,ROUNDUP((C16*1000/VLOOKUP(A16,Base_Donnees!A:F,3,FALSE))*1.5,0))) | G16: =IF(A16="","",VLOOKUP(A16,Base_Donnees!A:F,4,FALSE)) | H16: =IF(A16="","",VLOOKUP(A16,Base_Donnees!A:F,5,FALSE))
C17: =IF(A17="","",B17*$B$2) | D17: =IF(A17="","",VLOOKUP(A17,Base_Donnees!A:F,6,FALSE)) | E17: =IF(A17="","",C17*D17) | F17: =IF(A17="","",IF(VLOOKUP(A17,Base_Donnees!A:F,3,FALSE)>4000,0,ROUNDUP((C17*1000/VLOOKUP(A17,Base_Donnees!A:F,3,FALSE))*1.5,0))) | G17: =IF(A17="","",VLOOKUP(A17,Base_Donnees!A:F,4,FALSE)) | H17: =IF(A17="","",VLOOKUP(A17,Base_Donnees!A:F,5,FALSE))
C18: =IF(A18="","",B18*$B$2) | D18: =IF(A18="","",VLOOKUP(A18,Base_Donnees!A:F,6,FALSE)) | E18: =IF(A18="","",C18*D18) | F18: =IF(A18="","",IF(VLOOKUP(A18,Base_Donnees!A:F,3,FALSE)>4000,0,ROUNDUP((C18*1000/VLOOKUP(A18,Base_Donnees!A:F,3,FALSE))*1.5,0))) | G18: =IF(A18="","",VLOOKUP(A18,Base_Donnees!A:F,4,FALSE)) | H18: =IF(A18="","",VLOOKUP(A18,Base_Donnees!A:F,5,FALSE))
C19: =IF(A19="","",B19*$B$2) | D19: =IF(A19="","",VLOOKUP(A19,Base_Donnees!A:F,6,FALSE)) | E19: =IF(A19="","",C19*D19) | F19: =IF(A19="","",IF(VLOOKUP(A19,Base_Donnees!A:F,3,FALSE)>4000,0,ROUNDUP((C19*1000/VLOOKUP(A19,Base_Donnees!A:F,3,FALSE))*1.5,0))) | G19: =IF(A19="","",VLOOKUP(A19,Base_Donnees!A:F,4,FALSE)) | H19: =IF(A19="","",VLOOKUP(A19,Base_Donnees!A:F,5,FALSE))
C20: =IF(A20="","",B20*$B$2) | D20: =IF(A20="","",VLOOKUP(A20,Base_Donnees!A:F,6,FALSE)) | E20: =IF(A20="","",C20*D20) | F20: =IF(A20="","",IF(VLOOKUP(A20,Base_Donnees!A:F,3,FALSE)>4000,0,ROUNDUP((C20*1000/VLOOKUP(A20,Base_Donnees!A:F,3,FALSE))*1.5,0))) | G20: =IF(A20="","",VLOOKUP(A20,Base_Donnees!A:F,4,FALSE)) | H20: =IF(A20="","",VLOOKUP(A20,Base_Donnees!A:F,5,FALSE))
C21: =IF(A21="","",B21*$B$2) | D21: =IF(A21="","",VLOOKUP(A21,Base_Donnees!A:F,6,FALSE)) | E21: =IF(A21="","",C21*D21) | F21: =IF(A21="","",IF(VLOOKUP(A21,Base_Donnees!A:F,3,FALSE)>4000,0,ROUNDUP((C21*1000/VLOOKUP(A21,Base_Donnees!A:F,3,FALSE))*1.5,0))) | G21: =IF(A21="","",VLOOKUP(A21,Base_Donnees!A:F,4,FALSE)) | H21: =IF(A21="","",VLOOKUP(A21,Base_Donnees!A:F,5,FALSE))
C22: =IF(A22="","",B22*$B$2) | D22: =IF(A22="","",VLOOKUP(A22,Base_Donnees!A:F,6,FALSE)) | E22: =IF(A22="","",C22*D22) | F22: =IF(A22="","",IF(VLOOKUP(A22,Base_Donnees!A:F,3,FALSE)>4000,0,ROUNDUP((C22*1000/VLOOKUP(A22,Base_Donnees!A:F,3,FALSE))*1.5,0))) | G22: =IF(A22="","",VLOOKUP(A22,Base_Donnees!A:F,4,FALSE)) | H22: =IF(A22="","",VLOOKUP(A22,Base_Donnees!A:F,5,FALSE))
C23: =IF(A23="","",B23*$B$2) | D23: =IF(A23="","",VLOOKUP(A23,Base_Donnees!A:F,6,FALSE)) | E23: =IF(A23="","",C23*D23) | F23: =IF(A23="","",IF(VLOOKUP(A23,Base_Donnees!A:F,3,FALSE)>4000,0,ROUNDUP((C23*1000/VLOOKUP(A23,Base_Donnees!A:F,3,FALSE))*1.5,0))) | G23: =IF(A23="","",VLOOKUP(A23,Base_Donnees!A:F,4,FALSE)) | H23: =IF(A23="","",VLOOKUP(A23,Base_Donnees!A:F,5,FALSE))
A25: 👉 RÈGLES DU BAC C : ACIDES DE NETTOYAGE ET OLIGO-ÉLÉMENTS
A26: Produit (Menu Déroulant) | B26: Dose / Ha | C26: Dose TOTALE (Auto) | D26: Prix Unitaire | E26: Montant Ligne | F26: Eau Min (L) | G26: Temps (min) | H26: Règle de Sécurité / Note de Terrain
C27: =IF(A27="","",B27*$B$2) | D27: =IF(A27="","",VLOOKUP(A27,Base_Donnees!A:F,6,FALSE)) | E27: =IF(A27="","",C27*D27) | F27: =IF(A27="","",IF(VLOOKUP(A27,Base_Donnees!A:F,3,FALSE)>4000,0,ROUNDUP((C27*1000/VLOOKUP(A27,Base_Donnees!A:F,3,FALSE))*1.5,0))) | G27: =IF(A27="","",VLOOKUP(A27,Base_Donnees!A:F,4,FALSE)) | H27: =IF(A27="","",VLOOKUP(A27,Base_Donnees!A:F,5,FALSE))
C28: =IF(A28="","",B28*$B$2) | D28: =IF(A28="","",VLOOKUP(A28,Base_Donnees!A:F,6,FALSE)) | E28: =IF(A28="","",C28*D28) | F28: =IF(A28="","",IF(VLOOKUP(A28,Base_Donnees!A:F,3,FALSE)>4000,0,ROUNDUP((C28*1000/VLOOKUP(A28,Base_Donnees!A:F,3,FALSE))*1.5,0))) | G28: =IF(A28="","",VLOOKUP(A28,Base_Donnees!A:F,4,FALSE)) | H28: =IF(A28="","",VLOOKUP(A28,Base_Donnees!A:F,5,FALSE))
C29: =IF(A29="","",B29*$B$2) | D29: =IF(A29="","",VLOOKUP(A29,Base_Donnees!A:F,6,FALSE)) | E29: =IF(A29="","",C29*D29) | F29: =IF(A29="","",IF(VLOOKUP(A29,Base_Donnees!A:F,3,FALSE)>4000,0,ROUNDUP((C29*1000/VLOOKUP(A29,Base_Donnees!A:F,3,FALSE))*1.5,0))) | G29: =IF(A29="","",VLOOKUP(A29,Base_Donnees!A:F,4,FALSE)) | H29: =IF(A29="","",VLOOKUP(A29,Base_Donnees!A:F,5,FALSE))
A31: 👉 RÈGLES DU BAC D (SÉPARÉ) : ACIDE HUMIQUE ET FER CHÉLATÉ
A32: Produit (Menu Déroulant) | B32: Dose / Ha | C32: Dose TOTALE (Auto) | D32: Prix Unitaire | E32: Montant Ligne | F32: Eau Min (L) | G32: Temps (min) | H32: Règle de Sécurité / Note de Terrain
C33: =IF(A33="","",B33*$B$2) | D33: =IF(A33="","",VLOOKUP(A33,Base_Donnees!A:F,6,FALSE)) | E33: =IF(A33="","",C33*D33) | F33: =IF(A33="","",IF(VLOOKUP(A33,Base_Donnees!A:F,3,FALSE)>4000,0,ROUNDUP((C33*1000/VLOOKUP(A33,Base_Donnees!A:F,3,FALSE))*1.5,0))) | G33: =IF(A33="","",VLOOKUP(A33,Base_Donnees!A:F,4,FALSE)) | H33: =IF(A33="","",VLOOKUP(A33,Base_Donnees!A:F,5,FALSE))
C34: =IF(A34="","",B34*$B$2) | D34: =IF(A34="","",VLOOKUP(A34,Base_Donnees!A:F,6,FALSE)) | E34: =IF(A34="","",C34*D34) | F34: =IF(A34="","",IF(VLOOKUP(A34,Base_Donnees!A:F,3,FALSE)>4000,0,ROUNDUP((C34*1000/VLOOKUP(A34,Base_Donnees!A:F,3,FALSE))*1.5,0))) | G34: =IF(A34="","",VLOOKUP(A34,Base_Donnees!A:F,4,FALSE)) | H34: =IF(A34="","",VLOOKUP(A34,Base_Donnees!A:F,5,FALSE))
C35: =IF(A35="","",B35*$B$2) | D35: =IF(A35="","",VLOOKUP(A35,Base_Donnees!A:F,6,FALSE)) | E35: =IF(A35="","",C35*D35) | F35: =IF(A35="","",IF(VLOOKUP(A35,Base_Donnees!A:F,3,FALSE)>4000,0,ROUNDUP((C35*1000/VLOOKUP(A35,Base_Donnees!A:F,3,FALSE))*1.5,0))) | G35: =IF(A35="","",VLOOKUP(A35,Base_Donnees!A:F,4,FALSE)) | H35: =IF(A35="","",VLOOKUP(A35,Base_Donnees!A:F,5,FALSE))
A38: RÉSUMÉ COMPLÈT DE REMPLISSAGE ET COÛTS PAR BAC (RESTAURATION CUVE 1000L)
A39: Identifiant Bac | B39: Eau Initiale à Verser (L) | C39: Vol. Solution Estimé (L) | D39: Alerte Cuve 1000L | E39: Temps Agitation (min) | F39: Coût Total du Bac
A40: BAC A | B40: =SUM(F7:F9) -> 0 | C40: =B40+SUM(C7:C9)*0.6 -> 0 | D40: =IF(C40>1000,"TROP PLEIN !","OK") -> OK | E40: =IF(B40=0,0,MAX(G7:G9)) -> 0 | F40: =SUM(E7:E9) -> 0
A41: BAC B | B41: =SUM(F13:F23) -> 0 | C41: =B41+SUM(C13:C23)*0.6 -> 0 | D41: =IF(C41>1000,"TROP PLEIN !","OK") -> OK | E41: =IF(B41=0,0,MAX(G13:G23)) -> 0 | F41: =SUM(E13:E23) -> 0
A42: BAC C | B42: =SUM(F27:F29) -> 0 | C42: =B42+SUM(C27:C29)*0.6 -> 0 | D42: =IF(C42>1000,"TROP PLEIN !","OK") -> OK | E42: =IF(B42=0,0,MAX(G27:G29)) -> 0 | F42: =SUM(E27:E29) -> 0
A43: BAC D (SÉPARÉ) | B43: =SUM(F33:F35) -> 0 | C43: =B43+SUM(C33:C35)*0.6 -> 0 | D43: =IF(C43>1000,"TROP PLEIN !","OK") -> OK | E43: =IF(B43=0,0,MAX(G33:G35)) -> 0 | F43: =SUM(E33:E35) -> 0
F44: =SUM(F40:F43) -> 0

Sheet Modèle_A_Dupliquer (3)
A1: SUIVI LOGISTIQUE ET FINANCIER DES APPLICATIONS PAR BAC (V9) | F1: =F44 -> 0
A2: NOMBRE D'HECTARES : | B2: 1
A3: DATE D'APPLICATION : | B3: 46159
A5: 👉 RÈGLES DU BAC A : CUVES DU CALCIUM ET ACIDE NITRIQUE
A6: Produit (Menu Déroulant) | B6: Dose / Ha | C6: Dose TOTALE (Auto) | D6: Prix Unitaire | E6: Montant Ligne | F6: Eau Min (L) | G6: Temps (min) | H6: Règle de Sécurité / Note de Terrain
C7: =IF(A7="","",B7*$B$2) | D7: =IF(A7="","",VLOOKUP(A7,Base_Donnees!A:F,6,FALSE)) | E7: =IF(A7="","",C7*D7) | F7: =IF(A7="","",IF(VLOOKUP(A7,Base_Donnees!A:F,3,FALSE)>4000,0,ROUNDUP((C7*1000/VLOOKUP(A7,Base_Donnees!A:F,3,FALSE))*1.5,0))) | G7: =IF(A7="","",VLOOKUP(A7,Base_Donnees!A:F,4,FALSE)) | H7: =IF(A7="","",VLOOKUP(A7,Base_Donnees!A:F,5,FALSE))
C8: =IF(A8="","",B8*$B$2) | D8: =IF(A8="","",VLOOKUP(A8,Base_Donnees!A:F,6,FALSE)) | E8: =IF(A8="","",C8*D8) | F8: =IF(A8="","",IF(VLOOKUP(A8,Base_Donnees!A:F,3,FALSE)>4000,0,ROUNDUP((C8*1000/VLOOKUP(A8,Base_Donnees!A:F,3,FALSE))*1.5,0))) | G8: =IF(A8="","",VLOOKUP(A8,Base_Donnees!A:F,4,FALSE)) | H8: =IF(A8="","",VLOOKUP(A8,Base_Donnees!A:F,5,FALSE))
C9: =IF(A9="","",B9*$B$2) | D9: =IF(A9="","",VLOOKUP(A9,Base_Donnees!A:F,6,FALSE)) | E9: =IF(A9="","",C9*D9) | F9: =IF(A9="","",IF(VLOOKUP(A9,Base_Donnees!A:F,3,FALSE)>4000,0,ROUNDUP((C9*1000/VLOOKUP(A9,Base_Donnees!A:F,3,FALSE))*1.5,0))) | G9: =IF(A9="","",VLOOKUP(A9,Base_Donnees!A:F,4,FALSE)) | H9: =IF(A9="","",VLOOKUP(A9,Base_Donnees!A:F,5,FALSE))
A11: 👉 RÈGLES DU BAC B : CUVE ÉNERGIE & MACRO-ÉLÉMENTS (11 Lignes Disponibles)
A12: Produit (Menu Déroulant) | B12: Dose / Ha | C12: Dose TOTALE (Auto) | D12: Prix Unitaire | E12: Montant Ligne | F12: Eau Min (L) | G12: Temps (min) | H12: Règle de Sécurité / Note de Terrain
C13: =IF(A13="","",B13*$B$2) | D13: =IF(A13="","",VLOOKUP(A13,Base_Donnees!A:F,6,FALSE)) | E13: =IF(A13="","",C13*D13) | F13: =IF(A13="","",IF(VLOOKUP(A13,Base_Donnees!A:F,3,FALSE)>4000,0,ROUNDUP((C13*1000/VLOOKUP(A13,Base_Donnees!A:F,3,FALSE))*1.5,0))) | G13: =IF(A13="","",VLOOKUP(A13,Base_Donnees!A:F,4,FALSE)) | H13: =IF(A13="","",VLOOKUP(A13,Base_Donnees!A:F,5,FALSE))
C14: =IF(A14="","",B14*$B$2) | D14: =IF(A14="","",VLOOKUP(A14,Base_Donnees!A:F,6,FALSE)) | E14: =IF(A14="","",C14*D14) | F14: =IF(A14="","",IF(VLOOKUP(A14,Base_Donnees!A:F,3,FALSE)>4000,0,ROUNDUP((C14*1000/VLOOKUP(A14,Base_Donnees!A:F,3,FALSE))*1.5,0))) | G14: =IF(A14="","",VLOOKUP(A14,Base_Donnees!A:F,4,FALSE)) | H14: =IF(A14="","",VLOOKUP(A14,Base_Donnees!A:F,5,FALSE))
C15: =IF(A15="","",B15*$B$2) | D15: =IF(A15="","",VLOOKUP(A15,Base_Donnees!A:F,6,FALSE)) | E15: =IF(A15="","",C15*D15) | F15: =IF(A15="","",IF(VLOOKUP(A15,Base_Donnees!A:F,3,FALSE)>4000,0,ROUNDUP((C15*1000/VLOOKUP(A15,Base_Donnees!A:F,3,FALSE))*1.5,0))) | G15: =IF(A15="","",VLOOKUP(A15,Base_Donnees!A:F,4,FALSE)) | H15: =IF(A15="","",VLOOKUP(A15,Base_Donnees!A:F,5,FALSE))
C16: =IF(A16="","",B16*$B$2) | D16: =IF(A16="","",VLOOKUP(A16,Base_Donnees!A:F,6,FALSE)) | E16: =IF(A16="","",C16*D16) | F16: =IF(A16="","",IF(VLOOKUP(A16,Base_Donnees!A:F,3,FALSE)>4000,0,ROUNDUP((C16*1000/VLOOKUP(A16,Base_Donnees!A:F,3,FALSE))*1.5,0))) | G16: =IF(A16="","",VLOOKUP(A16,Base_Donnees!A:F,4,FALSE)) | H16: =IF(A16="","",VLOOKUP(A16,Base_Donnees!A:F,5,FALSE))
C17: =IF(A17="","",B17*$B$2) | D17: =IF(A17="","",VLOOKUP(A17,Base_Donnees!A:F,6,FALSE)) | E17: =IF(A17="","",C17*D17) | F17: =IF(A17="","",IF(VLOOKUP(A17,Base_Donnees!A:F,3,FALSE)>4000,0,ROUNDUP((C17*1000/VLOOKUP(A17,Base_Donnees!A:F,3,FALSE))*1.5,0))) | G17: =IF(A17="","",VLOOKUP(A17,Base_Donnees!A:F,4,FALSE)) | H17: =IF(A17="","",VLOOKUP(A17,Base_Donnees!A:F,5,FALSE))
C18: =IF(A18="","",B18*$B$2) | D18: =IF(A18="","",VLOOKUP(A18,Base_Donnees!A:F,6,FALSE)) | E18: =IF(A18="","",C18*D18) | F18: =IF(A18="","",IF(VLOOKUP(A18,Base_Donnees!A:F,3,FALSE)>4000,0,ROUNDUP((C18*1000/VLOOKUP(A18,Base_Donnees!A:F,3,FALSE))*1.5,0))) | G18: =IF(A18="","",VLOOKUP(A18,Base_Donnees!A:F,4,FALSE)) | H18: =IF(A18="","",VLOOKUP(A18,Base_Donnees!A:F,5,FALSE))
C19: =IF(A19="","",B19*$B$2) | D19: =IF(A19="","",VLOOKUP(A19,Base_Donnees!A:F,6,FALSE)) | E19: =IF(A19="","",C19*D19) | F19: =IF(A19="","",IF(VLOOKUP(A19,Base_Donnees!A:F,3,FALSE)>4000,0,ROUNDUP((C19*1000/VLOOKUP(A19,Base_Donnees!A:F,3,FALSE))*1.5,0))) | G19: =IF(A19="","",VLOOKUP(A19,Base_Donnees!A:F,4,FALSE)) | H19: =IF(A19="","",VLOOKUP(A19,Base_Donnees!A:F,5,FALSE))
C20: =IF(A20="","",B20*$B$2) | D20: =IF(A20="","",VLOOKUP(A20,Base_Donnees!A:F,6,FALSE)) | E20: =IF(A20="","",C20*D20) | F20: =IF(A20="","",IF(VLOOKUP(A20,Base_Donnees!A:F,3,FALSE)>4000,0,ROUNDUP((C20*1000/VLOOKUP(A20,Base_Donnees!A:F,3,FALSE))*1.5,0))) | G20: =IF(A20="","",VLOOKUP(A20,Base_Donnees!A:F,4,FALSE)) | H20: =IF(A20="","",VLOOKUP(A20,Base_Donnees!A:F,5,FALSE))
C21: =IF(A21="","",B21*$B$2) | D21: =IF(A21="","",VLOOKUP(A21,Base_Donnees!A:F,6,FALSE)) | E21: =IF(A21="","",C21*D21) | F21: =IF(A21="","",IF(VLOOKUP(A21,Base_Donnees!A:F,3,FALSE)>4000,0,ROUNDUP((C21*1000/VLOOKUP(A21,Base_Donnees!A:F,3,FALSE))*1.5,0))) | G21: =IF(A21="","",VLOOKUP(A21,Base_Donnees!A:F,4,FALSE)) | H21: =IF(A21="","",VLOOKUP(A21,Base_Donnees!A:F,5,FALSE))
C22: =IF(A22="","",B22*$B$2) | D22: =IF(A22="","",VLOOKUP(A22,Base_Donnees!A:F,6,FALSE)) | E22: =IF(A22="","",C22*D22) | F22: =IF(A22="","",IF(VLOOKUP(A22,Base_Donnees!A:F,3,FALSE)>4000,0,ROUNDUP((C22*1000/VLOOKUP(A22,Base_Donnees!A:F,3,FALSE))*1.5,0))) | G22: =IF(A22="","",VLOOKUP(A22,Base_Donnees!A:F,4,FALSE)) | H22: =IF(A22="","",VLOOKUP(A22,Base_Donnees!A:F,5,FALSE))
C23: =IF(A23="","",B23*$B$2) | D23: =IF(A23="","",VLOOKUP(A23,Base_Donnees!A:F,6,FALSE)) | E23: =IF(A23="","",C23*D23) | F23: =IF(A23="","",IF(VLOOKUP(A23,Base_Donnees!A:F,3,FALSE)>4000,0,ROUNDUP((C23*1000/VLOOKUP(A23,Base_Donnees!A:F,3,FALSE))*1.5,0))) | G23: =IF(A23="","",VLOOKUP(A23,Base_Donnees!A:F,4,FALSE)) | H23: =IF(A23="","",VLOOKUP(A23,Base_Donnees!A:F,5,FALSE))
A25: 👉 RÈGLES DU BAC C : ACIDES DE NETTOYAGE ET OLIGO-ÉLÉMENTS
A26: Produit (Menu Déroulant) | B26: Dose / Ha | C26: Dose TOTALE (Auto) | D26: Prix Unitaire | E26: Montant Ligne | F26: Eau Min (L) | G26: Temps (min) | H26: Règle de Sécurité / Note de Terrain
C27: =IF(A27="","",B27*$B$2) | D27: =IF(A27="","",VLOOKUP(A27,Base_Donnees!A:F,6,FALSE)) | E27: =IF(A27="","",C27*D27) | F27: =IF(A27="","",IF(VLOOKUP(A27,Base_Donnees!A:F,3,FALSE)>4000,0,ROUNDUP((C27*1000/VLOOKUP(A27,Base_Donnees!A:F,3,FALSE))*1.5,0))) | G27: =IF(A27="","",VLOOKUP(A27,Base_Donnees!A:F,4,FALSE)) | H27: =IF(A27="","",VLOOKUP(A27,Base_Donnees!A:F,5,FALSE))
C28: =IF(A28="","",B28*$B$2) | D28: =IF(A28="","",VLOOKUP(A28,Base_Donnees!A:F,6,FALSE)) | E28: =IF(A28="","",C28*D28) | F28: =IF(A28="","",IF(VLOOKUP(A28,Base_Donnees!A:F,3,FALSE)>4000,0,ROUNDUP((C28*1000/VLOOKUP(A28,Base_Donnees!A:F,3,FALSE))*1.5,0))) | G28: =IF(A28="","",VLOOKUP(A28,Base_Donnees!A:F,4,FALSE)) | H28: =IF(A28="","",VLOOKUP(A28,Base_Donnees!A:F,5,FALSE))
C29: =IF(A29="","",B29*$B$2) | D29: =IF(A29="","",VLOOKUP(A29,Base_Donnees!A:F,6,FALSE)) | E29: =IF(A29="","",C29*D29) | F29: =IF(A29="","",IF(VLOOKUP(A29,Base_Donnees!A:F,3,FALSE)>4000,0,ROUNDUP((C29*1000/VLOOKUP(A29,Base_Donnees!A:F,3,FALSE))*1.5,0))) | G29: =IF(A29="","",VLOOKUP(A29,Base_Donnees!A:F,4,FALSE)) | H29: =IF(A29="","",VLOOKUP(A29,Base_Donnees!A:F,5,FALSE))
A31: 👉 RÈGLES DU BAC D (SÉPARÉ) : ACIDE HUMIQUE ET FER CHÉLATÉ
A32: Produit (Menu Déroulant) | B32: Dose / Ha | C32: Dose TOTALE (Auto) | D32: Prix Unitaire | E32: Montant Ligne | F32: Eau Min (L) | G32: Temps (min) | H32: Règle de Sécurité / Note de Terrain
C33: =IF(A33="","",B33*$B$2) | D33: =IF(A33="","",VLOOKUP(A33,Base_Donnees!A:F,6,FALSE)) | E33: =IF(A33="","",C33*D33) | F33: =IF(A33="","",IF(VLOOKUP(A33,Base_Donnees!A:F,3,FALSE)>4000,0,ROUNDUP((C33*1000/VLOOKUP(A33,Base_Donnees!A:F,3,FALSE))*1.5,0))) | G33: =IF(A33="","",VLOOKUP(A33,Base_Donnees!A:F,4,FALSE)) | H33: =IF(A33="","",VLOOKUP(A33,Base_Donnees!A:F,5,FALSE))
C34: =IF(A34="","",B34*$B$2) | D34: =IF(A34="","",VLOOKUP(A34,Base_Donnees!A:F,6,FALSE)) | E34: =IF(A34="","",C34*D34) | F34: =IF(A34="","",IF(VLOOKUP(A34,Base_Donnees!A:F,3,FALSE)>4000,0,ROUNDUP((C34*1000/VLOOKUP(A34,Base_Donnees!A:F,3,FALSE))*1.5,0))) | G34: =IF(A34="","",VLOOKUP(A34,Base_Donnees!A:F,4,FALSE)) | H34: =IF(A34="","",VLOOKUP(A34,Base_Donnees!A:F,5,FALSE))
C35: =IF(A35="","",B35*$B$2) | D35: =IF(A35="","",VLOOKUP(A35,Base_Donnees!A:F,6,FALSE)) | E35: =IF(A35="","",C35*D35) | F35: =IF(A35="","",IF(VLOOKUP(A35,Base_Donnees!A:F,3,FALSE)>4000,0,ROUNDUP((C35*1000/VLOOKUP(A35,Base_Donnees!A:F,3,FALSE))*1.5,0))) | G35: =IF(A35="","",VLOOKUP(A35,Base_Donnees!A:F,4,FALSE)) | H35: =IF(A35="","",VLOOKUP(A35,Base_Donnees!A:F,5,FALSE))
A38: RÉSUMÉ COMPLÈT DE REMPLISSAGE ET COÛTS PAR BAC (RESTAURATION CUVE 1000L)
