Workbook

Sheet Mars_Avril_Mai_1H30
A1: PLANNING D'IRRIGATION SÉQUENTIEL (VINCENT) - CYCLE DE PRINTEMPS (MARS - MI-MAI)
A3: Règle du cycle en vigueur : Total 1h30 par bloc (30m eau + 45m engrais + 15m lavage)
A5: 📅 PÉRIODE : MARS À MI-MAI
A6: Parcelle / Bloc | B6: Heure Début | C6: 💧 Pré-mouillage | D6: 🧪 Injection Bacs (Programme) | E6: 🚿 Rinçage Réseau | F6: Heure Fin | G6: Durée Minutes
A7: JOUR 1 : Nectarines & Pommiers (Départ 05h00)
A8: 🍑 Nectarines : Nabara | B8: 0.20833333 | C8: 05h00 - 05h30 (30 min) | D8: 05h30 - 06h15 (45 min) | E8: 06h15 - 06h30 (15 min) | F8: =B8+G8/1440 -> 0.27083333 | G8: 90
A9: ⏳ Pause Technique / Basculement Vannes : 06h30 - 06h40 (10 min) | G9: 10
A10: 🍑 Nectarines : REDIX® 25 | B10: =F8+G9/1440 -> 0.27777778 | C10: 06h40 - 07h10 (30 min) | D10: 07h10 - 07h55 (45 min) | E10: 07h55 - 08h10 (15 min) | F10: =B10+G10/1440 -> 0.34027778 | G10: 90
A11: ⏳ Pause Technique / Basculement Vannes : 08h10 - 08h20 (10 min) | G11: 10
A12: 🍏 Pommiers : Parcelles 1 et 2 | B12: =F10+G11/1440 -> 0.34722222 | C12: 08h20 - 08h50 (30 min) | D12: 08h50 - 09h35 (45 min) | E12: 09h35 - 09h50 (15 min) | F12: =B12+G12/1440 -> 0.40972222 | G12: 90
A13: JOUR 2 : Oliviers (Départ 05h00)
A14: 🫒 Oliviers : Parcelles 1 et 2 | B14: 0.20833333 | C14: 05h00 - 05h30 (30 min) | D14: 05h30 - 06h15 (45 min) | E14: 06h15 - 06h30 (15 min) | F14: =B14+G14/1440 -> 0.27083333 | G14: 90
A15: ⏳ Pause Technique / Basculement Vannes : 06h30 - 06h40 (10 min) | G15: 10
A16: 🫒 Oliviers : Parcelles 3 et 4 | B16: =F14+G15/1440 -> 0.27777778 | C16: 06h40 - 07h10 (30 min) | D16: 07h10 - 07h55 (45 min) | E16: 07h55 - 08h10 (15 min) | F16: =B16+G16/1440 -> 0.34027778 | G16: 90
A17: ⏳ Pause Technique / Basculement Vannes : 08h10 - 08h20 (10 min) | G17: 10
A18: 🫒 Casuarina | B18: =F16+G17/1440 -> 0.34722222 | C18: 08h20 - 08h50 (30 min) | D18: 08h50 - 09h35 (45 min) | E18: 09h35 - 09h50 (15 min) | F18: =B18+G18/1440 -> 0.40972222 | G18: 90

Sheet Fin_Mai_Juin_2H30
A1: PLANNING D'IRRIGATION SÉQUENTIEL (VINCENT) - CYCLE D'ÉTÉ (À PARTIR DU 28 MAI & JUIN)
A3: Règle du cycle en vigueur : Total 2h30 par bloc (1h30 eau + 45m engrais + 15m lavage)
A5: 📅 PÉRIODE : À PARTIR DU 28 MAI & JUIN
A6: Parcelle / Bloc | B6: Heure Début | C6: 💧 Pré-mouillage | D6: 🧪 Injection Bacs (Programme) | E6: 🚿 Rinçage Réseau | F6: Heure Fin | G6: Durée Minutes
A7: JOUR 1 : Nectarines & Pommiers (Départ 03h00)
A8: 🍑 Nectarines : Nabara | B8: 0.125 | C8: 03h00 - 04h30 (1h30) | D8: 04h30 - 05h15 (45 min) | E8: 05h15 - 05h30 (15 min) | F8: =B8+G8/1440 -> 0.22916667 | G8: 150
A9: ⏳ Pause Technique / Basculement Vannes : 05h30 - 05h40 (10 min) | G9: 10
A10: 🍑 Nectarines : REDIX® 25 | B10: =F8+G9/1440 -> 0.23611111 | C10: 05h40 - 07h10 (1h30) | D10: 07h10 - 07h55 (45 min) | E10: 07h55 - 08h10 (15 min) | F10: =B10+G10/1440 -> 0.34027778 | G10: 150
A11: ⏳ Pause Technique / Basculement Vannes : 08h10 - 08h20 (10 min) | G11: 10
A12: 🍏 Pommiers : Parcelles 1 et 2 | B12: =F10+G11/1440 -> 0.34722222 | C12: 08h20 - 09h50 (1h30) | D12: 09h50 - 10h35 (45 min) | E12: 10h35 - 10h50 (15 min) | F12: =B12+G12/1440 -> 0.45138889 | G12: 150
A13: JOUR 2 : Oliviers (Départ 03h00)
A14: 🫒 Oliviers : Parcelles 1 et 2 | B14: 0.125 | C14: 03h00 - 04h30 (1h30) | D14: 04h30 - 05h15 (45 min) | E14: 05h15 - 05h30 (15 min) | F14: =B14+G14/1440 -> 0.22916667 | G14: 150
A15: ⏳ Pause Technique / Basculement Vannes : 05h30 - 05h40 (10 min) | G15: 10
A16: 🫒 Oliviers : Parcelles 3 et 4 | B16: =F14+G15/1440 -> 0.23611111 | C16: 05h40 - 07h10 (1h30) | D16: 07h10 - 07h55 (45 min) | E16: 07h55 - 08h10 (15 min) | F16: =B16+G16/1440 -> 0.34027778 | G16: 150
A17: ⏳ Pause Technique / Basculement Vannes : 08h10 - 08h20 (10 min) | G17: 10
A18: 🫒 Casuarina | B18: =F16+G17/1440 -> 0.34722222 | C18: 08h20 - 09h50 (1h30) | D18: 09h50 - 10h35 (45 min) | E18: 10h35 - 10h50 (15 min) | F18: =B18+G18/1440 -> 0.45138889 | G18: 150

Sheet Base_Donnees
A1: Produit / Commercial Name | B1: Catégorie | C1: Solubilité (g/L) / DAR | D1: Temps Réf / Matière Active | E1: Note de Terrain / Cible Spécifique | F1: Prix Unitaire (DA) | G1: Contenant (kg - L) | H1: Dose Homologuée | I1: Photo | J1: Fournisseur | K1: Quantité Acheter | L1: Montant Total
A2: Nitrate de Calcium / نترات كالسـيوم | B2: Fertigation - Bac A | C2: 120 | D2: 6 min | E2: CRITIQUE : Isoler totalement des Sulfates/Phosphates. | F2: 160 | G2: KG | J2: Agrimax | K2: 400 | L2: =K2*F2 -> 64000
A3: Urée / يوريا | B3: Fertigation - Bac B | C3: 105 | D3: 5 min | E3: Très soluble. Refroidit l'eau (endothermique). | F3: 45 | G3: KG | J3: Agrimax | K3: 300 | L3: =K3*F3 -> 13500
A4: Nitrate de Potassium / نترات البوتاسيوم | B4: Fertigation - Bac B | C4: 30 | D4: 15 min | E4: Sensible à l'eau froide du puits. | F4: 26 | G4: KG | J4: Agrimax | K4: 300 | L4: =K4*F4 -> 7800
A5: Sulfate de Potassium / سلفات البوتاسيوم SOP | B5: Fertigation - Bac B | C5: 10 | D5: 20 min | E5: Le plus difficile à dissoudre du marché. | F5: 220 | G5: KG | J5: Agrimax | K5: 1000 | L5: =K5*F5 -> 220000
A6: Nitrate de Magnésium / نترات ماغنسيوم | B6: Fertigation - Bac B | C6: 70 | D6: 8 min | E6: Excellente source de magnésium soluble. | F6: 260 | G6: KG | J6: Agrimax | K6: 150 | L6: =K6*F6 -> 39000
A7: Sulfate de Magnésium / سلفات ماغنسيوم | B7: Fertigation - Bac B | F7: 240 | G7: KG | J7: Agrimax | K7: 125 | L7: =K7*F7 -> 30000
A8: Oligo-éléments / عناصر صغري | B8: Fertigation - Bac C | C8: 60 | D8: 10 min | E8: Mélange complet d'oligo-éléments chélatés. | F8: 3450 | G8: KG | J8: Agrimax | K8: 30 | L8: =K8*F8 -> 103500
A9: Acide Humique / أسمدة عضوية | B9: Fertigation - Bac C | C9: 50 | D9: 15 min | E9: Améliore la structure du sol et l'assimilation. | F9: 420 | G9: L | J9: Agrimax | K9: 20 | L9: =K9*F9 -> 8400
A10: Fer 6% / حديد 6% | B10: Fertigation - Bac C | C10: 90 | D10: 8 min | E10: Indispensable contre la chlorose en sol calcaire. | F10: 3200 | G10: KG | J10: Agrimax | K10: 30 | L10: =K10*F10 -> 96000
A11: Fer 6% / حديد 6% | B11: Fertigation - Bac C | C11: 90 | D11: 8 min | E11: Indispensable contre la chlorose en sol calcaire. | F11: 2700 | G11: KG | J11: Agro Rafik | K11: 1 | L11: =K11*F11 -> 2700
A12: GZB Stimulateur de racines / منشط جذور | B12: Fertigation - Bac C | C12: Liquide | D12: - | E12: Stimulant organique complexe à injecter à part. | F12: 2200 | G12: L | J12: NSDA | K12: 10 | L12: =K12*F12 -> 22000
A13: Acide Nitrique / حامض نيتريك | B13: Fertigation - Bac D | C13: 5000 | D13: 1 min | E13: CORROSIF : Gants + lunettes obligatoires. | F13: 378.15 | G13: L | J13: Agrimax | K13: 400 | L13: =K13*F13 -> 151260
A14: Acide Nitrique AGRIZOTE/ حامض نيتريك | B14: Fertigation - Bac D | C14: 5000 | D14: 1 min | E14: CORROSIF : Gants + lunettes obligatoires. | F14: 177.31 | G14: L | J14: HYGINDUST | K14: 1 | L14: =K14*F14 -> 177.31
A15: Acide Phosphorique AGRIPHOS / حامض فوسفوريك | B15: Fertigation - Bac D | C15: 5000 | D15: 1 min | E15: Sécurité : Toujours verser l'acide dans l'eau. | F15: 664 | G15: L | J15: HYGINDUST | K15: 1 | L15: =K15*F15 -> 664
A16: Acide Phosphorique / حامض فوسفوريك | B16: Fertigation - Bac D | C16: 5000 | D16: 1 min | E16: Sécurité : Toujours verser l'acide dans l'eau. | F16: 500 | G16: L | J16: Agrimax | K16: 600 | L16: =K16*F16 -> 300000
A17: Acide Citrique / حامض سيتريك | B17: Fertigation - Bac D | C17: 590 | D17: 4 min | E17: Idéal pour chélater et nettoyer les goutteurs. | F17: 410.55 | G17: KG | J17: HYGINDUST | K17: 500 | L17: =K17*F17 -> 205275
A18: Acide Ascorbique / اسكوربيك اسيد | B18: Fertigation - Bac D | C18: 330 | D18: 5 min | E18: Soutient la plante contre le stress thermique saharien. | F18: 3000 | G18: KG | J18: BLIDA | K18: 75 | L18: =K18*F18 -> 225000
A19: Acides Aminés 80% / أحماض أمينية | B19: Pulvérisation Foliaire | C19: Poudre | D19: Relance végétative | E19: Anti-stress foliaire post-Sirocco. | F19: 1500 | G19: L | L19: =K19*F19 -> 0
A20: Algreen / طحالب بحرية | B20: Pulvérisation Foliaire | C20: Liquide | D20: Extrait d'algues | E20: Soutien de la vigueur foliaire et division. | F20: 2000 | G20: L | J20: Agrimax | K20: 36 | L20: =K20*F20 -> 72000
A21: Calcium-Bore Foliaire / كالسيوم بورون | B21: Pulvérisation Foliaire | C21: Liquide | D21: Fermeté fruit | E21: Appliquer aux stades critiques du fruit. | F21: 550 | G21: L | J21: Agrimax | K21: 30 | L21: =K21*F21 -> 16500
A22: Soufre Micronisé / كبريت ميكروني | B22: Pulvérisation Foliaire | C22: Poudre | D22: Fongicide | E22: Traitement préventif oïdium/tavelure. | F22: 400 | G22: KG | L22: =K22*F22 -> 0
A23: Gibbérelline 10% / جبريليك | B23: Pulvérisation Foliaire | C23: Pastille | D23: Hormonal | E23: Allongement et calibre cellulaire (5 pastilles/1000L). | F23: 2000 | G23: L | L23: =K23*F23 -> 0
A24: Cytokinine / سيتوكينين | B24: Pulvérisation Foliaire | C24: Liquide | D24: Hormone | E24: Division cellulaire | F24: 2500 | G24: L | L24: =K24*F24 -> 0
A25: Produit / Commercial Name | B25: Catégorie | C25: DAR | D25: Matière Active | E25: Note de Terrain / Cible Spécifique | F25: Prix Unitaire (DA) | G25: Contenant (kg - L) | H25: Dose Homologuée | I25: Photo | J25: Fournisseur | K25: Quantité Acheter | L25: Montant Total
A26: Calypso | B26: Phytosanitaire | C26: 14 Jours | D26: Thiaclopride | E26: Insecticide systémique (Pucerons, Carpocapse du pommier) | F26: 20000 | G26: 1 L | H26: 20 à 30 cc / hl | J26: Agrimax | K26: 1 | L26: =K26*F26 -> 20000
A27: Sivento | B27: Phytosanitaire | C27: 14 Jours | D27: Flupyradifurone | E27: Excellente systémie (Pucerons, Aleurodes) | F27: 10000 | G27: 1 L | H27: 0,5 L / ha | J27: Agrimax | K27: 1 | L27: =K27*F27 -> 10000
A28: Verlan | B28: Phytosanitaire | C28: 14 Jours | D28: Abamectine | E28: Action translaminaire (Acariens, Mineuses) | F28: 11000 | G28: 1L | H28: 40 à 50 cc / hl | J28: Agrimax | K28: 1 | L28: =K28*F28 -> 11000
A29: Bellis | B29: Phytosanitaire | C29: 7 Jours | D29: Boscalid + Pyraclostrobine | E29: Spécifique arbres à noyau (Coryneum du nectarinier, Oïdium) | F29: 24000 | G29: 1 kg | H29: 30 à 50 g / hl | J29: Agro Bahbah | K29: 2 | L29: =K29*F29 -> 48000
A30: Erlan | B30: Phytosanitaire | C30: 14 Jours | D30: Acétamipride (Gamme locale) | E30: Insectes piqueurs-suceurs | F30: 2300 | G30: 1,02 L | H30: 200 à 300 g / ha | J30: Agro Rafik | K30: 1 | L30: =K30*F30 -> 2300
A31: Sherpa 25 EC | B31: Phytosanitaire | C31: 14 Jours | D31: Cyperméthrine | E31: Effet de choc par contact (Psylle de l'olivier, Noctuelles) | F31: 1600 | G31: 0,250 L | H31: 0,5 L / ha | J31: Agro Rafik | K31: 1 | L31: =K31*F31 -> 1600
A32: Decis Expert | B32: Phytosanitaire | C32: 7 Jours | D32: Deltaméthrine | E32: Large spectre, action foudroyante | F32: 3200 | G32: 0,250 L | H32: 250 ml / ha | J32: Agrimax | K32: 1 | L32: =K32*F32 -> 3200
A33: Acetaplan | B33: Phytosanitaire | C33: 14 Jours | D33: Acetamipride | E33: Insecticide systémiques | F33: 2000 | G33: 1 L | J33: Agrimax | K33: 1 | L33: =K33*F33 -> 2000
A34: Amistar | B34: Phytosanitaire | C34: 7 Jours | D34: Azoxystrobine | E34: Fongicide préventif large spectre | F34: 4500 | G34: 1 L | H34: 0,8 à 1 L / ha | J34: Agrimax | K34: 1 | L34: =K34*F34 -> 4500
A35: Azostar 325SC | B35: Phytosanitaire | C35: 14 Jours | D35: Azoxystrobine + Difénoconazole | E35: Double action (Tavelure du pommier, Oïdium) | F35: 1000 | G35: 1 L | H35: 0,75 à 1 L / ha | J35: Agrimax | K35: 1 | L35: =K35*F35 -> 1000
A36: Zorro | B36: Phytosanitaire | C36: 30 Jours | D36: Abamectine (Formulation EW) | E36: Acaricide de référence (Acariens rouges) | F36: 1000 | G36: 1 L | H36: 40 à 50 cc / hl | J36: Agrimax | K36: 1 | L36: =K36*F36 -> 1000
A37: Fosetyl Aluminium | B37: Phytosanitaire | C37: 14 - 21 Jours | D37: Fosétyl-Al (ex: Aliette) | E37: Systémie ascendante/descendante (Phytophthora, Mildiou) | F37: 3500 | G37: 1 Kg | H37: 2,5 kg / ha | J37: Agro Rafik | K37: 20 | L37: =K37*F37 -> 70000
A38: Luna | B38: Phytosanitaire | C38: 3 - 7 j | D38: Fluopyram + Trifloxystrobine | E38: Très haute efficacité (Monilia, Tavelure, Oïdium) | F38: 19250 | G38: 1 L | H38: 0,3 à 0,4 L / ha | J38: Agro Rafik | K38: 1.5 | L38: =K38*F38 -> 28875
A39: Criptan | B39: Phytosanitaire | C39: 14 - 21 Jours | D39: Captane | E39: Fongicide de contact (Tavelure, Monilia) | F39: 2800 | G39: 1 Kg | H39: 1,5 à 2 kg / ha | J39: Agro Rafik | K39: 4 | L39: =K39*F39 -> 11200
A40: Extrachim | B40: Phytosanitaire | C40: 13 Jours | D40: Gamme de distribution | E40: Distributeur local proposant plusieurs matières actives | F40: 750 | G40: 0,1 Kg | H40: Selon le produit | J40: Agro Rafik | K40: 20 | L40: =K40*F40 -> 15000
...

Sheet Résumé_Fournisseurs
A1: RÉSUMÉ GLOBAL PAR FOURNISSEUR
A3: Fournisseur | B3: Montant Total (DA) | C3: Pourcentage
A4: Agrimax | B4: 1170660 | C4: 0.62098994
A5: BLIDA | B5: 225000 | C5: 0.11935381
A6: HYGINDUST | B6: 206116.31 | C6: 0.10933675
A7: Agro Rafik | B7: 195375 | C7: 0.1036389
A8: Agro Bahbah | B8: 48000 | C8: 0.025462147
A9: NSDA | B9: 22000 | C9: 0.011670151
A10: Agro Kamel | B10: 18000 | C10: 0.0095483052
A11: TOTAL GLOBAL | B11: 1885151.3 | C11: 1

Sheet Résumé_Par_Espèce
A1: RÉSUMÉ GLOBAL DES COÛTS PAR ESPÈCE
A3: ESPÈCE : NECTARINE | F3: Numéros Prog
A4: Programme / Date | B4: Fertigation (DA) | C4: Pulvérisation (DA) | D4: Phytosanitaire (DA) | E4: Coût Total (DA)
A5: 09 Mars Nectarine | B5: ='09_Mars_Nectarine'!F44 -> 16907.4 | C5: ='09_Mars_Nectarine'!F51 -> 36000 | D5: ='09_Mars_Nectarine'!F58 -> 48000 | E5: =SUM(B5:D5) -> 100907.4 | F5: 1
A6: 01 Avril Nectarine | B6: ='01_Avril_Nectarine'!F44 -> 22797 | C6: ='01_Avril_Nectarine'!F51 -> 32700 | D6: ='01_Avril_Nectarine'!F58 -> 0 | E6: =SUM(B6:D6) -> 55497 | F6: 2
A7: 20 Avril Nectarine | B7: ='20_Avril_Nectarine'!F46 -> 51239.8 | C7: ='20_Avril_Nectarine'!F53 -> 5500 | D7: ='20_Avril_Nectarine'!F60 -> 18002 | E7: =SUM(B7:D7) -> 74741.8 | F7: 3
A8: 06 Mai Nectarine | B8: ='06_Mai_Nectarine'!F45 -> 60996 | C8: ='06_Mai_Nectarine'!F52 -> 32700 | D8: ='06_Mai_Nectarine'!F59 -> 2 | E8: =SUM(B8:D8) -> 93698 | F8: 4
A9: 28 Mai Nectarine REDEX 25 | B9: ='28_Mai_Nectarine_RED'!F45 -> 59695.6 | C9: ='28_Mai_Nectarine_RED'!F52 -> 55700 | D9: ='28_Mai_Nectarine_RED'!F59 -> 0 | E9: =SUM(B9:D9) -> 115395.6 | F9: 5
A10: 28 Mai Nectarine 2 | B10: ='28_Mai_Nectarine_NAB'!F47 -> 145408.8 | C10: ='28_Mai_Nectarine_NAB'!F55 -> 55700 | D10: ='28_Mai_Nectarine_NAB'!F62 -> 0 | E10: =SUM(B10:D10) -> 201108.8 | F10: 6
A11: SOUS-TOTAL NECTARINE | B11: =SUM(B5:B10) -> 357044.6 | C11: =SUM(C5:C10) -> 218300 | D11: =SUM(D5:D10) -> 66004 | E11: =SUM(E5:E10) -> 641348.6
A13: ESPÈCE : POMMIER
A14: Programme / Date | B14: Fertigation (DA) | C14: Pulvérisation (DA) | D14: Phytosanitaire (DA) | E14: Coût Total (DA)
A15: 09 Mars Pommier | B15: ='09_Mars_Pommier'!F24 -> 13500 | C15: ='09_Mars_Pommier'!F31 -> 2400 | D15: ='09_Mars_Pommier'!F38 -> 0 | E15: =SUM(B15:D15) -> 15900 | F15: 7
A16: 01 Avril Pommier | B16: ='01_Avril_Pommier'!F44 -> 13208.5 | C16: ='01_Avril_Pommier'!F51 -> 6650 | D16: ='01_Avril_Pommier'!F58 -> 24000 | E16: =SUM(B16:D16) -> 43858.5 | F16: 8
A17: 06 Mai Pommier | B17: ='06_Mai_Pommier'!F44 -> 22372.3 | C17: ='06_Mai_Pommier'!F51 -> 21100 | D17: ='06_Mai_Pommier'!F58 -> 1 | E17: =SUM(B17:D17) -> 43473.3 | F17: 9
A18: 28 Mai Pommier | B18: ='28_Mai_Pommier'!F44 -> 22684.3 | C18: ='28_Mai_Pommier'!F51 -> 21100 | D18: ='28_Mai_Pommier'!F58 -> 20001 | E18: =SUM(B18:D18) -> 63785.3 | F18: 10
A19: SOUS-TOTAL POMMIER | B19: =SUM(B15:B18) -> 71765.1 | C19: =SUM(C15:C18) -> 51250 | D19: =SUM(D15:D18) -> 44002 | E19: =SUM(E15:E18) -> 167017.1
A21: ESPÈCE : OLIVIER
A22: Programme / Date | B22: Fertigation (DA) | C22: Pulvérisation (DA) | D22: Phytosanitaire (DA) | E22: Coût Total (DA)
A23: 17 Mars Olivier | B23: ='17_Mars_Olivier'!F43 -> 34672.4 | C23: ='17_Mars_Olivier'!F50 -> 0 | D23: ='17_Mars_Olivier'!F57 -> 0 | E23: =SUM(B23:D23) -> 34672.4 | F23: 11
A24: 06 Mai Olivier | B24: ='06_Mai_Olivier'!F44 -> 76092.4 | C24: ='06_Mai_Olivier'!F51 -> 0 | D24: ='06_Mai_Olivier'!F58 -> 0 | E24: =SUM(B24:D24) -> 76092.4 | F24: 12
A25: 28 Mai Olivier | B25: ='28_Mai_Olivier'!F45 -> 76091.2 | C25: ='28_Mai_Olivier'!F52 -> 0 | D25: ='28_Mai_Olivier'!F59 -> 0 | E25: =SUM(B25:D25) -> 76091.2 | F25: 13
A26: SOUS-TOTAL OLIVIER | B26: =SUM(B23:B25) -> 186856 | C26: =SUM(C23:C25) -> 0 | D26: =SUM(D23:D25) -> 0 | E26: =SUM(E23:E25) -> 186856
A28: COÛT GLOBAL DE TOUS LES PROGRAMMES : | E28: =E11+E19+E26 -> 995221.7

Sheet 09_Mars_Nectarine
A1: PROGRAMME DE PRÉCISION DOUBLE - NECTARINE : NABLARA et REDIX® 25
A3: NOMBRE D'HECTARES : | B3: 4
A4: DATE DU PROGRAMME : | B4: 2026-03-09
A5: ESPÈCE / PARCELLE : | B5: Nectarine : Nablara et REDIX® 25
A7: PROGRAMME 01
A8: 👉 RÈGLES DU BAC A : CUVES DU CALCIUM
A9: Produit (Réf Base) | B9: Dose / Ha / App | C9: Apps / Semaine | D9: Dose TOTALE Hebdo | E9: Prix Unitaire (DA) | F9: Montant Total Hebdo | G9: Eau Min (L) | H9: Temps dissolution | I9: Note Logistique
D10: =IF(AND(ISNUMBER(B10), ISNUMBER(C10)), B10*C10*$B$3, "") | E10: =IF(A10="","",VLOOKUP(A10, Base_Donnees!A:F, 6, FALSE)) | F10: =IF(ISNUMBER(D10), D10*E10, "") | G10: =IF(A10="","",IF(ISNUMBER(D10), IFERROR((D10/VLOOKUP(A10, Base_Donnees!A:F, 3, FALSE))*1000, "-"), "")) | H10: =IF(A10="","",VLOOKUP(A10, Base_Donnees!A:F, 4, FALSE)) | I10: =IF(A10="","",VLOOKUP(A10, Base_Donnees!A:F, 5, FALSE))
A12: 👉 RÈGLES DU BAC B : CUVE ÉNERGIE & MACRO-ÉLÉMENTS
A13: Produit (Réf Base) | B13: Dose / Ha / App | C13: Apps / Semaine | D13: Dose TOTALE Hebdo | E13: Prix Unitaire (DA) | F13: Montant Total Hebdo | G13: Eau Min (L) | H13: Temps dissolution | I13: Note Logistique
A14: Urée / يوريا | B14: 2 | C14: 1 | D14: =IF(AND(ISNUMBER(B14), ISNUMBER(C14)), B14*C14*$B$3, "") -> 8 | E14: =IF(A14="","",VLOOKUP(A14, Base_Donnees!A:F, 6, FALSE)) -> 45 | F14: =IF(ISNUMBER(D14), D14*E14, "") -> 360 | G14: =IF(A14="","",IF(ISNUMBER(D14), IFERROR((D14/VLOOKUP(A14, Base_Donnees!A:F, 3, FALSE))*1000, "-"), "")) -> 76.190476 | H14: =IF(A14="","",VLOOKUP(A14, Base_Donnees!A:F, 4, FALSE)) -> 5 min | I14: =IF(A14="","",VLOOKUP(A14, Base_Donnees!A:F, 5, FALSE)) -> Très soluble. Refroidit l'eau (endothermique).
A15: Sulfate de Potassium / سلفات البوتاسيوم SOP | B15: 3.5 | C15: 1 | D15: =IF(AND(ISNUMBER(B15), ISNUMBER(C15)), B15*C15*$B$3, "") -> 14 | E15: =IF(A15="","",VLOOKUP(A15, Base_Donnees!A:F, 6, FALSE)) -> 220 | F15: =IF(ISNUMBER(D15), D15*E15, "") -> 3080 | G15: =IF(A15="","",IF(ISNUMBER(D15), IFERROR((D15/VLOOKUP(A15, Base_Donnees!A:F, 3, FALSE))*1000, "-"), "")) -> 1400 | H15: =IF(A15="","",VLOOKUP(A15, Base_Donnees!A:F, 4, FALSE)) -> 20 min | I15: =IF(A15="","",VLOOKUP(A15, Base_Donnees!A:F, 5, FALSE)) -> Le plus difficile à dissoudre du marché.
A16: Nitrate de Magnésium / نترات ماغنسيوم | B16: 1.5 | C16: 1 | D16: =IF(AND(ISNUMBER(B16), ISNUMBER(C16)), B16*C16*$B$3, "") -> 6 | E16: =IF(A16="","",VLOOKUP(A16, Base_Donnees!A:F, 6, FALSE)) -> 260 | F16: =IF(ISNUMBER(D16), D16*E16, "") -> 1560 | G16: =IF(A16="","",IF(ISNUMBER(D16), IFERROR((D16/VLOOKUP(A16, Base_Donnees!A:F, 3, FALSE))*1000, "-"), "")) -> 85.714286 | H16: =IF(A16="","",VLOOKUP(A16, Base_Donnees!A:F, 4, FALSE)) -> 8 min | I16: =IF(A16="","",VLOOKUP(A16, Base_Donnees!A:F, 5, FALSE)) -> Excellente source de magnésium soluble.
A18: 👉 RÈGLES DU BAC C : OLIGO-ÉLÉMENTS, ACIDE HUMIQUE
A19: Produit (Réf Base) | B19: Dose / Ha / App | C19: Apps / Semaine | D19: Dose TOTALE Hebdo | E19: Prix Unitaire (DA) | F19: Montant Total Hebdo | G19: Eau Min (L) | H19: Temps dissolution | I19: Note Logistique
D20: =IF(AND(ISNUMBER(B20), ISNUMBER(C20)), B20*C20*$B$3, "") | E20: =IF(A20="","",VLOOKUP(A20, Base_Donnees!A:F, 6, FALSE)) | F20: =IF(ISNUMBER(D20), D20*E20, "") | G20: =IF(A20="","",IF(ISNUMBER(D20), IFERROR((D20/VLOOKUP(A20, Base_Donnees!A:F, 3, FALSE))*1000, "-"), "")) | H20: =IF(A20="","",VLOOKUP(A20, Base_Donnees!A:F, 4, FALSE)) | I20: =IF(A20="","",VLOOKUP(A20, Base_Donnees!A:F, 5, FALSE))
A22: 👉 RÈGLES DU BAC D (SÉPARÉ) : ACIDES DE NETTOYAGE
A23: Produit (Réf Base) | B23: Dose / Ha / App | C23: Apps / Semaine | D23: Dose TOTALE Hebdo | E23: Prix Unitaire (DA) | F23: Montant Total Hebdo | G23: Eau Min (L) | H23: Temps dissolution | I23: Note Logistique
A24: Acide Phosphorique / حامض فوسفوريك | B24: 2.5 | C24: 1 | D24: =IF(AND(ISNUMBER(B24), ISNUMBER(C24)), B24*C24*$B$3, "") -> 10 | E24: =IF(A24="","",VLOOKUP(A24, Base_Donnees!A:F, 6, FALSE)) -> 500 | F24: =IF(ISNUMBER(D24), D24*E24, "") -> 5000 | G24: =IF(A24="","",IF(ISNUMBER(D24), IFERROR((D24/VLOOKUP(A24, Base_Donnees!A:F, 3, FALSE))*1000, "-"), "")) -> 2 | H24: =IF(A24="","",VLOOKUP(A24, Base_Donnees!A:F, 4, FALSE)) -> 1 min | I24: =IF(A24="","",VLOOKUP(A24, Base_Donnees!A:F, 5, FALSE)) -> Sécurité : Toujours verser l'acide dans l'eau.
A26: PROGRAMME 02
A27: 👉 RÈGLES DU BAC A : CUVES DU CALCIUM
A28: Produit (Réf Base) | B28: Dose / Ha / App | C28: Apps / Semaine | D28: Dose TOTALE Hebdo | E28: Prix Unitaire (DA) | F28: Montant Total Hebdo | G28: Eau Min (L) | H28: Temps dissolution | I28: Note Logistique
A29: Nitrate de Calcium / نترات كالسـيوم | B29: 3.5 | C29: 1 | D29: =IF(AND(ISNUMBER(B29), ISNUMBER(C29)), B29*C29*$B$3, "") -> 14 | E29: =IF(A29="","",VLOOKUP(A29, Base_Donnees!A:F, 6, FALSE)) -> 160 | F29: =IF(ISNUMBER(D29), D29*E29, "") -> 2240 | G29: =IF(A29="","",IF(ISNUMBER(D29), IFERROR((D29/VLOOKUP(A29, Base_Donnees!A:F, 3, FALSE))*1000, "-"), "")) -> 116.66667 | H29: =IF(A29="","",VLOOKUP(A29, Base_Donnees!A:F, 4, FALSE)) -> 6 min | I29: =IF(A29="","",VLOOKUP(A29, Base_Donnees!A:F, 5, FALSE)) -> CRITIQUE : Isoler totalement des Sulfates/Phosphates.
A31: 👉 RÈGLES DU BAC B : CUVE ÉNERGIE & MACRO-ÉLÉMENTS
A32: Produit (Réf Base) | B32: Dose / Ha / App | C32: Apps / Semaine | D32: Dose TOTALE Hebdo | E32: Prix Unitaire (DA) | F32: Montant Total Hebdo | G32: Eau Min (L) | H32: Temps dissolution | I32: Note Logistique
D33: =IF(AND(ISNUMBER(B33), ISNUMBER(C33)), B33*C33*$B$3, "") | E33: =IF(A33="","",VLOOKUP(A33, Base_Donnees!A:F, 6, FALSE)) | F33: =IF(ISNUMBER(D33), D33*E33, "") | G33: =IF(A33="","",IF(ISNUMBER(D33), IFERROR((D33/VLOOKUP(A33, Base_Donnees!A:F, 3, FALSE))*1000, "-"), "")) | H33: =IF(A33="","",VLOOKUP(A33, Base_Donnees!A:F, 4, FALSE)) | I33: =IF(A33="","",VLOOKUP(A33, Base_Donnees!A:F, 5, FALSE))
A35: 👉 RÈGLES DU BAC C : OLIGO-ÉLÉMENTS, ACIDE HUMIQUE
A36: Produit (Réf Base) | B36: Dose / Ha / App | C36: Apps / Semaine | D36: Dose TOTALE Hebdo | E36: Prix Unitaire (DA) | F36: Montant Total Hebdo | G36: Eau Min (L) | H36: Temps dissolution | I36: Note Logistique
D37: =IF(AND(ISNUMBER(B37), ISNUMBER(C37)), B37*C37*$B$3, "") | E37: =IF(A37="","",VLOOKUP(A37, Base_Donnees!A:F, 6, FALSE)) | F37: =IF(ISNUMBER(D37), D37*E37, "") | G37: =IF(A37="","",IF(ISNUMBER(D37), IFERROR((D37/VLOOKUP(A37, Base_Donnees!A:F, 3, FALSE))*1000, "-"), "")) | H37: =IF(A37="","",VLOOKUP(A37, Base_Donnees!A:F, 4, FALSE)) | I37: =IF(A37="","",VLOOKUP(A37, Base_Donnees!A:F, 5, FALSE))
A39: 👉 RÈGLES DU BAC D (SÉPARÉ) : ACIDES DE NETTOYAGE
A40: Produit (Réf Base) | B40: Dose / Ha / App | C40: Apps / Semaine | D40: Dose TOTALE Hebdo | E40: Prix Unitaire (DA) | F40: Montant Total Hebdo | G40: Eau Min (L) | H40: Temps dissolution | I40: Note Logistique
A41: Acide Nitrique / حامض نيتريك | B41: 2 | C41: 1 | D41: =IF(AND(ISNUMBER(B41), ISNUMBER(C41)), B41*C41*$B$3, "") -> 8 | E41: =IF(A41="","",VLOOKUP(A41, Base_Donnees!A:F, 6, FALSE)) -> 378.15 | F41: =IF(ISNUMBER(D41), D41*E41, "") -> 3025.2 | G41: =IF(A41="","",IF(ISNUMBER(D41), IFERROR((D41/VLOOKUP(A41, Base_Donnees!A:F, 3, FALSE))*1000, "-"), "")) -> 1.6 | H41: =IF(A41="","",VLOOKUP(A41, Base_Donnees!A:F, 4, FALSE)) -> 1 min | I41: =IF(A41="","",VLOOKUP(A41, Base_Donnees!A:F, 5, FALSE)) -> CORROSIF : Gants + lunettes obligatoires.
A42: Acide Citrique / حامض سيتريك | B42: 1 | C42: 1 | D42: =IF(AND(ISNUMBER(B42), ISNUMBER(C42)), B42*C42*$B$3, "") -> 4 | E42: =IF(A42="","",VLOOKUP(A42, Base_Donnees!A:F, 6, FALSE)) -> 410.55 | F42: =IF(ISNUMBER(D42), D42*E42, "") -> 1642.2 | G42: =IF(A42="","",IF(ISNUMBER(D42), IFERROR((D42/VLOOKUP(A42, Base_Donnees!A:F, 3, FALSE))*1000, "-"), "")) -> 6.779661 | H42: =IF(A42="","",VLOOKUP(A42, Base_Donnees!A:F, 4, FALSE)) -> 4 min | I42: =IF(A42="","",VLOOKUP(A42, Base_Donnees!A:F, 5, FALSE)) -> Idéal pour chélater et nettoyer les goutteurs.
E44: TOTAL FERTIGATION : | F44: =SUM(F10,F14,F15,F16,F20,F24,F29,F33,F37,F41,F42) -> 16907.4
A46: 🍃 PROGRAMME DE PULVÉRISATION FOLIAIRE & BIOSTIMULANTS
A47: Produit Sélectionné | B47: Dose Réf | C47: Hectares | D47: Dose Totale | E47: Prix Unitaire (DA) | F47: Coût Total | G47: Note Technique | H47: Cible
A48: Calcium-Bore Foliaire / كالسيوم بورون | B48: 1.5 | C48: =$B$3 -> 4 | D48: =IF(ISNUMBER(B48), B48*C48, "") -> 6 | E48: =IF(A48="","",VLOOKUP(A48, Base_Donnees!A:F, 6, FALSE)) -> 550 | F48: =IF(ISNUMBER(D48), D48*E48, "") -> 3300 | G48: =IF(A48="","",VLOOKUP(A48, Base_Donnees!A:F, 5, FALSE)) -> Appliquer aux stades critiques du fruit. | H48: =IF(A48="","",VLOOKUP(A48, Base_Donnees!A:F, 4, FALSE)) -> Fermeté fruit
A49: Algreen / طحالب بحرية | B49: 1.5 | C49: =$B$3 -> 4 | D49: =IF(ISNUMBER(B49), B49*C49, "") -> 6 | E49: =IF(A49="","",VLOOKUP(A49, Base_Donnees!A:F, 6, FALSE)) -> 2000 | F49: =IF(ISNUMBER(D49), D49*E49, "") -> 12000 | G49: =IF(A49="","",VLOOKUP(A49, Base_Donnees!A:F, 5, FALSE)) -> Soutien de la vigueur foliaire et division. | H49: =IF(A49="","",VLOOKUP(A49, Base_Donnees!A:F, 4, FALSE)) -> Extrait d'algues
A50: Oligo-éléments / عناصر صغري | B50: 1.5 | C50: =$B$3 -> 4 | D50: =IF(ISNUMBER(B50), B50*C50, "") -> 6 | E50: =IF(A50="","",VLOOKUP(A50, Base_Donnees!A:F, 6, FALSE)) -> 3450 | F50: =IF(ISNUMBER(D50), D50*E50, "") -> 20700 | G50: =IF(A50="","",VLOOKUP(A50, Base_Donnees!A:F, 5, FALSE)) -> Mélange complet d'oligo-éléments chélatés. | H50: =IF(A50="","",VLOOKUP(A50, Base_Donnees!A:F, 4, FALSE)) -> 10 min
E51: TOTAL PULVÉRISATION : | F51: =SUM(F48,F49,F50) -> 36000
...

Sheet 09_Mars_Pommier
A1: PROGRAMME DE PRÉCISION DOUBLE - POMMIER : POMMIER 1
A3: NOMBRE D'HECTARES : | B3: 2
A4: DATE DU PROGRAMME : | B4: 2026-03-09
A5: ESPÈCE / PARCELLE : | B5: Pommier : Pommier 1 et 2
A7: PROGRAMME 01
A8: 👉 RÈGLES DU BAC A : CUVES DU CALCIUM
A9: Produit (Réf Base) | B9: Dose / Ha / App | C9: Apps / Semaine | D9: Dose TOTALE Hebdo | E9: Prix Unitaire (DA) | F9: Montant Total Hebdo | G9: Eau Min (L) | H9: Temps dissolution | I9: Note Logistique
D10: =IF(AND(ISNUMBER(B10), ISNUMBER(C10)), B10*C10*$B$3, "") | E10: =IF(A10="","",VLOOKUP(A10, Base_Donnees!A:F, 6, FALSE)) | F10: =IF(ISNUMBER(D10), D10*E10, "") | G10: =IF(A10="","",IF(ISNUMBER(D10), IFERROR((D10/VLOOKUP(A10, Base_Donnees!A:F, 3, FALSE))*1000, "-"), "")) | H10: =IF(A10="","",VLOOKUP(A10, Base_Donnees!A:F, 4, FALSE)) | I10: =IF(A10="","",VLOOKUP(A10, Base_Donnees!A:F, 5, FALSE))
A12: 👉 RÈGLES DU BAC B : CUVE ÉNERGIE & MACRO-ÉLÉMENTS
A13: Produit (Réf Base) | B13: Dose / Ha / App | C13: Apps / Semaine | D13: Dose TOTALE Hebdo | E13: Prix Unitaire (DA) | F13: Montant Total Hebdo | G13: Eau Min (L) | H13: Temps dissolution | I13: Note Logistique
D14: =IF(AND(ISNUMBER(B14), ISNUMBER(C14)), B14*C14*$B$3, "") | E14: =IF(A14="","",VLOOKUP(A14, Base_Donnees!A:F, 6, FALSE)) | F14: =IF(ISNUMBER(D14), D14*E14, "") | G14: =IF(A14="","",IF(ISNUMBER(D14), IFERROR((D14/VLOOKUP(A14, Base_Donnees!A:F, 3, FALSE))*1000, "-"), "")) | H14: =IF(A14="","",VLOOKUP(A14, Base_Donnees!A:F, 4, FALSE)) | I14: =IF(A14="","",VLOOKUP(A14, Base_Donnees!A:F, 5, FALSE))
A16: 👉 RÈGLES DU BAC C : OLIGO-ÉLÉMENTS, ACIDE HUMIQUE
A17: Produit (Réf Base) | B17: Dose / Ha / App | C17: Apps / Semaine | D17: Dose TOTALE Hebdo | E17: Prix Unitaire (DA) | F17: Montant Total Hebdo | G17: Eau Min (L) | H17: Temps dissolution | I17: Note Logistique
A18: GZB Stimulateur de racines / منشط جذور | B18: 2.5 | C18: 1 | D18: =IF(AND(ISNUMBER(B18), ISNUMBER(C18)), B18*C18*$B$3, "") -> 5 | E18: =IF(A18="","",VLOOKUP(A18, Base_Donnees!A:F, 6, FALSE)) -> 2200 | F18: =IF(ISNUMBER(D18), D18*E18, "") -> 11000 | G18: =IF(A18="","",IF(ISNUMBER(D18), IFERROR((D18/VLOOKUP(A18, Base_Donnees!A:F, 3, FALSE))*1000, "-"), "")) -> - | H18: =IF(A18="","",VLOOKUP(A18, Base_Donnees!A:F, 4, FALSE)) -> - | I18: =IF(A18="","",VLOOKUP(A18, Base_Donnees!A:F, 5, FALSE)) -> Stimulant organique complexe à injecter à part.
A20: 👉 RÈGLES DU BAC D (SÉPARÉ) : ACIDES DE NETTOYAGE
A21: Produit (Réf Base) | B21: Dose / Ha / App | C21: Apps / Semaine | D21: Dose TOTALE Hebdo | E21: Prix Unitaire (DA) | F21: Montant Total Hebdo | G21: Eau Min (L) | H21: Temps dissolution | I21: Note Logistique
A22: Acide Phosphorique / حامض فوسفوريك | B22: 2.5 | C22: 1 | D22: =IF(AND(ISNUMBER(B22), ISNUMBER(C22)), B22*C22*$B$3, "") -> 5 | E22: =IF(A22="","",VLOOKUP(A22, Base_Donnees!A:F, 6, FALSE)) -> 500 | F22: =IF(ISNUMBER(D22), D22*E22, "") -> 2500 | G22: =IF(A22="","",IF(ISNUMBER(D22), IFERROR((D22/VLOOKUP(A22, Base_Donnees!A:F, 3, FALSE))*1000, "-"), "")) -> 1 | H22: =IF(A22="","",VLOOKUP(A22, Base_Donnees!A:F, 4, FALSE)) -> 1 min | I22: =IF(A22="","",VLOOKUP(A22, Base_Donnees!A:F, 5, FALSE)) -> Sécurité : Toujours verser l'acide dans l'eau.
E24: TOTAL FERTIGATION : | F24: =SUM(F10,F14,F18,F22) -> 13500
A26: 🍃 PROGRAMME DE PULVÉRISATION FOLIAIRE & BIOSTIMULANTS
A27: Produit Sélectionné | B27: Dose Réf | C27: Hectares | D27: Dose Totale | E27: Prix Unitaire (DA) | F27: Coût Total | G27: Note Technique | H27: Cible
A28: Soufre Micronisé / كبريت ميكروني | B28: 3 | C28: =$B$3 -> 2 | D28: =IF(ISNUMBER(B28), B28*C28, "") -> 6 | E28: =IF(A28="","",VLOOKUP(A28, Base_Donnees!A:F, 6, FALSE)) -> 400 | F28: =IF(ISNUMBER(D28), D28*E28, "") -> 2400 | G28: =IF(A28="","",VLOOKUP(A28, Base_Donnees!A:F, 5, FALSE)) -> Traitement préventif oïdium/tavelure. | H28: =IF(A28="","",VLOOKUP(A28, Base_Donnees!A:F, 4, FALSE)) -> Fongicide
C29: =$B$3 -> 2 | D29: =IF(ISNUMBER(B29), B29*C29, "") | E29: =IF(A29="","",VLOOKUP(A29, Base_Donnees!A:F, 6, FALSE)) | F29: =IF(ISNUMBER(D29), D29*E29, "") | G29: =IF(A29="","",VLOOKUP(A29, Base_Donnees!A:F, 5, FALSE)) | H29: =IF(A29="","",VLOOKUP(A29, Base_Donnees!A:F, 4, FALSE))
C30: =$B$3 -> 2 | D30: =IF(ISNUMBER(B30), B30*C30, "") | E30: =IF(A30="","",VLOOKUP(A30, Base_Donnees!A:F, 6, FALSE)) | F30: =IF(ISNUMBER(D30), D30*E30, "") | G30: =IF(A30="","",VLOOKUP(A30, Base_Donnees!A:F, 5, FALSE)) | H30: =IF(A30="","",VLOOKUP(A30, Base_Donnees!A:F, 4, FALSE))
E31: TOTAL PULVÉRISATION : | F31: =SUM(F28,F29,F30) -> 2400
A33: 🛡️ PROGRAMME DE TRAITEMENT PHYTOSANITAIRE
A34: Spécialité Commerciale | B34: Dose Ha | C34: Hectares | D34: Dose Totale | E34: Prix Unitaire (DA) | F34: Coût Total | G34: DAR | H34: Matière Active | I34: Note
C35: =$B$3 -> 2 | D35: =IF(ISNUMBER(B35), B35*C35, "") | E35: =IF(A35="","",VLOOKUP(A35, Base_Donnees!A:F, 6, FALSE)) | F35: =IF(ISNUMBER(D35), D35*E35, "") | G35: =IF(A35="","",VLOOKUP(A35, Base_Donnees!A:F, 3, FALSE)) | H35: =IF(A35="","",VLOOKUP(A35, Base_Donnees!A:F, 4, FALSE)) | I35: =IF(A35="","",VLOOKUP(A35, Base_Donnees!A:F, 5, FALSE))
C36: =$B$3 -> 2 | D36: =IF(ISNUMBER(B36), B36*C36, "") | E36: =IF(A36="","",VLOOKUP(A36, Base_Donnees!A:F, 6, FALSE)) | F36: =IF(ISNUMBER(D36), D36*E36, "") | G36: =IF(A36="","",VLOOKUP(A36, Base_Donnees!A:F, 3, FALSE)) | H36: =IF(A36="","",VLOOKUP(A36, Base_Donnees!A:F, 4, FALSE)) | I36: =IF(A36="","",VLOOKUP(A36, Base_Donnees!A:F, 5, FALSE))
C37: =$B$3 -> 2 | D37: =IF(ISNUMBER(B37), B37*C37, "") | E37: =IF(A37="","",VLOOKUP(A37, Base_Donnees!A:F, 6, FALSE)) | F37: =IF(ISNUMBER(D37), D37*E37, "") | G37: =IF(A37="","",VLOOKUP(A37, Base_Donnees!A:F, 3, FALSE)) | H37: =IF(A37="","",VLOOKUP(A37, Base_Donnees!A:F, 4, FALSE)) | I37: =IF(A37="","",VLOOKUP(A37, Base_Donnees!A:F, 5, FALSE))
E38: TOTAL PHYTOSANITAIRE : | F38: =SUM(F35,F36,F37) -> 0

Sheet 17_Mars_Olivier
A1: PROGRAMME DE PRÉCISION DOUBLE - NECTARINE / POMMIER
A3: NOMBRE D'HECTARES : | B3: 8
A4: DATE DU PROGRAMME : | B4: 2026-03-17
A5: ESPÈCE / PARCELLE : | B5: Oliviers Parcelle (1 a 4)
A7: PROGRAMME 01
A8: 👉 RÈGLES DU BAC A : CUVES DU CALCIUM
A9: Produit (Réf Base) | B9: Dose / Ha / App | C9: Apps / Semaine | D9: Dose TOTALE Hebdo | E9: Prix Unitaire (DA) | F9: Montant Total Hebdo | G9: Eau Min (L) | H9: Temps dissolution | I9: Note Logistique
D10: =IF(AND(ISNUMBER(B10), ISNUMBER(C10)), B10*C10*$B$3, "") | E10: =IF(A10="","",VLOOKUP(A10, Base_Donnees!A:F, 6, FALSE)) | F10: =IF(ISNUMBER(D10), D10*E10, "") | G10: =IF(A10="","",IF(ISNUMBER(D10), IFERROR((D10/VLOOKUP(A10, Base_Donnees!A:F, 3, FALSE))*1000, "-"), "")) | H10: =IF(A10="","",VLOOKUP(A10, Base_Donnees!A:F, 4, FALSE)) | I10: =IF(A10="","",VLOOKUP(A10, Base_Donnees!A:F, 5, FALSE))
A12: 👉 RÈGLES DU BAC B : CUVE ÉNERGIE & MACRO-ÉLÉMENTS
A13: Produit (Réf Base) | B13: Dose / Ha / App | C13: Apps / Semaine | D13: Dose TOTALE Hebdo | E13: Prix Unitaire (DA) | F13: Montant Total Hebdo | G13: Eau Min (L) | H13: Temps dissolution | I13: Note Logistique
A14: Urée / يوريا | B14: 2 | C14: 1 | D14: =IF(AND(ISNUMBER(B14), ISNUMBER(C14)), B14*C14*$B$3, "") -> 16 | E14: =IF(A14="","",VLOOKUP(A14, Base_Donnees!A:F, 6, FALSE)) -> 45 | F14: =IF(ISNUMBER(D14), D14*E14, "") -> 720 | G14: =IF(A14="","",IF(ISNUMBER(D14), IFERROR((D14/VLOOKUP(A14, Base_Donnees!A:F, 3, FALSE))*1000, "-"), "")) -> 152.38095 | H14: =IF(A14="","",VLOOKUP(A14, Base_Donnees!A:F, 4, FALSE)) -> 5 min | I14: =IF(A14="","",VLOOKUP(A14, Base_Donnees!A:F, 5, FALSE)) -> Très soluble. Refroidit l'eau (endothermique).
A15: Nitrate de Potassium / نترات البوتاسيوم | B15: 3.5 | C15: 1 | D15: =IF(AND(ISNUMBER(B15), ISNUMBER(C15)), B15*C15*$B$3, "") -> 28 | E15: =IF(A15="","",VLOOKUP(A15, Base_Donnees!A:F, 6, FALSE)) -> 26 | F15: =IF(ISNUMBER(D15), D15*E15, "") -> 728 | G15: =IF(A15="","",IF(ISNUMBER(D15), IFERROR((D15/VLOOKUP(A15, Base_Donnees!A:F, 3, FALSE))*1000, "-"), "")) -> 933.33333 | H15: =IF(A15="","",VLOOKUP(A15, Base_Donnees!A:F, 4, FALSE)) -> 15 min | I15: =IF(A15="","",VLOOKUP(A15, Base_Donnees!A:F, 5, FALSE)) -> Sensible à l'eau froide du puits.
A16: Nitrate de Magnésium / نترات ماغنسيوم | B16: 2 | C16: 1 | D16: =IF(AND(ISNUMBER(B16), ISNUMBER(C16)), B16*C16*$B$3, "") -> 16 | E16: =IF(A16="","",VLOOKUP(A16, Base_Donnees!A:F, 6, FALSE)) -> 260 | F16: =IF(ISNUMBER(D16), D16*E16, "") -> 4160 | G16: =IF(A16="","",IF(ISNUMBER(D16), IFERROR((D16/VLOOKUP(A16, Base_Donnees!A:F, 3, FALSE))*1000, "-"), "")) -> 228.57143 | H16: =IF(A16="","",VLOOKUP(A16, Base_Donnees!A:F, 4, FALSE)) -> 8 min | I16: =IF(A16="","",VLOOKUP(A16, Base_Donnees!A:F, 5, FALSE)) -> Excellente source de magnésium soluble.
A18: 👉 RÈGLES DU BAC C : OLIGO-ÉLÉMENTS, ACIDE HUMIQUE
A19: Produit (Réf Base) | B19: Dose / Ha / App | C19: Apps / Semaine | D19: Dose TOTALE Hebdo | E19: Prix Unitaire (DA) | F19: Montant Total Hebdo | G19: Eau Min (L) | H19: Temps dissolution | I19: Note Logistique
A20: Fer 6% / حديد 6% | B20: 0.25 | C20: 1 | D20: =IF(AND(ISNUMBER(B20), ISNUMBER(C20)), B20*C20*$B$3, "") -> 2 | E20: =IF(A20="","",VLOOKUP(A20, Base_Donnees!A:F, 6, FALSE)) -> 3200 | F20: =IF(ISNUMBER(D20), D20*E20, "") -> 6400 | G20: =IF(A20="","",IF(ISNUMBER(D20), IFERROR((D20/VLOOKUP(A20, Base_Donnees!A:F, 3, FALSE))*1000, "-"), "")) -> 22.222222 | H20: =IF(A20="","",VLOOKUP(A20, Base_Donnees!A:F, 4, FALSE)) -> 8 min | I20: =IF(A20="","",VLOOKUP(A20, Base_Donnees!A:F, 5, FALSE)) -> Indispensable contre la chlorose en sol calcaire.
A22: 👉 RÈGLES DU BAC D (SÉPARÉ) : ACIDES DE NETTOYAGE
A23: Produit (Réf Base) | B23: Dose / Ha / App | C23: Apps / Semaine | D23: Dose TOTALE Hebdo | E23: Prix Unitaire (DA) | F23: Montant Total Hebdo | G23: Eau Min (L) | H23: Temps dissolution | I23: Note Logistique
A24: Acide Phosphorique / حامض فوسفوريك | B24: 2.5 | C24: 1 | D24: =IF(AND(ISNUMBER(B24), ISNUMBER(C24)), B24*C24*$B$3, "") -> 20 | E24: =IF(A24="","",VLOOKUP(A24, Base_Donnees!A:F, 6, FALSE)) -> 500 | F24: =IF(ISNUMBER(D24), D24*E24, "") -> 10000 | G24: =IF(A24="","",IF(ISNUMBER(D24), IFERROR((D24/VLOOKUP(A24, Base_Donnees!A:F, 3, FALSE))*1000, "-"), "")) -> 4 | H24: =IF(A24="","",VLOOKUP(A24, Base_Donnees!A:F, 4, FALSE)) -> 1 min | I24: =IF(A24="","",VLOOKUP(A24, Base_Donnees!A:F, 5, FALSE)) -> Sécurité : Toujours verser l'acide dans l'eau.
A26: PROGRAMME 02
A27: 👉 RÈGLES DU BAC A : CUVES DU CALCIUM
A28: Produit (Réf Base) | B28: Dose / Ha / App | C28: Apps / Semaine | D28: Dose TOTALE Hebdo | E28: Prix Unitaire (DA) | F28: Montant Total Hebdo | G28: Eau Min (L) | H28: Temps dissolution | I28: Note Logistique
A29: Nitrate de Calcium / نترات كالسـيوم | B29: 2.5 | C29: 1 | D29: =IF(AND(ISNUMBER(B29), ISNUMBER(C29)), B29*C29*$B$3, "") -> 20 | E29: =IF(A29="","",VLOOKUP(A29, Base_Donnees!A:F, 6, FALSE)) -> 160 | F29: =IF(ISNUMBER(D29), D29*E29, "") -> 3200 | G29: =IF(A29="","",IF(ISNUMBER(D29), IFERROR((D29/VLOOKUP(A29, Base_Donnees!A:F, 3, FALSE))*1000, "-"), "")) -> 166.66667 | H29: =IF(A29="","",VLOOKUP(A29, Base_Donnees!A:F, 4, FALSE)) -> 6 min | I29: =IF(A29="","",VLOOKUP(A29, Base_Donnees!A:F, 5, FALSE)) -> CRITIQUE : Isoler totalement des Sulfates/Phosphates.
A31: 👉 RÈGLES DU BAC B : CUVE ÉNERGIE & MACRO-ÉLÉMENTS
A32: Produit (Réf Base) | B32: Dose / Ha / App | C32: Apps / Semaine | D32: Dose TOTALE Hebdo | E32: Prix Unitaire (DA) | F32: Montant Total Hebdo | G32: Eau Min (L) | H32: Temps dissolution | I32: Note Logistique
D33: =IF(AND(ISNUMBER(B33), ISNUMBER(C33)), B33*C33*$B$3, "") | E33: =IF(A33="","",VLOOKUP(A33, Base_Donnees!A:F, 6, FALSE)) | F33: =IF(ISNUMBER(D33), D33*E33, "") | G33: =IF(A33="","",IF(ISNUMBER(D33), IFERROR((D33/VLOOKUP(A33, Base_Donnees!A:F, 3, FALSE))*1000, "-"), "")) | H33: =IF(A33="","",VLOOKUP(A33, Base_Donnees!A:F, 4, FALSE)) | I33: =IF(A33="","",VLOOKUP(A33, Base_Donnees!A:F, 5, FALSE))
A35: 👉 RÈGLES DU BAC C : OLIGO-ÉLÉMENTS, ACIDE HUMIQUE
A36: Produit (Réf Base) | B36: Dose / Ha / App | C36: Apps / Semaine | D36: Dose TOTALE Hebdo | E36: Prix Unitaire (DA) | F36: Montant Total Hebdo | G36: Eau Min (L) | H36: Temps dissolution | I36: Note Logistique
D37: =IF(AND(ISNUMBER(B37), ISNUMBER(C37)), B37*C37*$B$3, "") | E37: =IF(A37="","",VLOOKUP(A37, Base_Donnees!A:F, 6, FALSE)) | F37: =IF(ISNUMBER(D37), D37*E37, "") | G37: =IF(A37="","",IF(ISNUMBER(D37), IFERROR((D37/VLOOKUP(A37, Base_Donnees!A:F, 3, FALSE))*1000, "-"), "")) | H37: =IF(A37="","",VLOOKUP(A37, Base_Donnees!A:F, 4, FALSE)) | I37: =IF(A37="","",VLOOKUP(A37, Base_Donnees!A:F, 5, FALSE))
A39: 👉 RÈGLES DU BAC D (SÉPARÉ) : ACIDES DE NETTOYAGE
A40: Produit (Réf Base) | B40: Dose / Ha / App | C40: Apps / Semaine | D40: Dose TOTALE Hebdo | E40: Prix Unitaire (DA) | F40: Montant Total Hebdo | G40: Eau Min (L) | H40: Temps dissolution | I40: Note Logistique
A41: Acide Nitrique / حامض نيتريك | B41: 1.5 | C41: 1 | D41: =IF(AND(ISNUMBER(B41), ISNUMBER(C41)), B41*C41*$B$3, "") -> 12 | E41: =IF(A41="","",VLOOKUP(A41, Base_Donnees!A:F, 6, FALSE)) -> 378.15 | F41: =IF(ISNUMBER(D41), D41*E41, "") -> 4537.8 | G41: =IF(A41="","",IF(ISNUMBER(D41), IFERROR((D41/VLOOKUP(A41, Base_Donnees!A:F, 3, FALSE))*1000, "-"), "")) -> 2.4 | H41: =IF(A41="","",VLOOKUP(A41, Base_Donnees!A:F, 4, FALSE)) -> 1 min | I41: =IF(A41="","",VLOOKUP(A41, Base_Donnees!A:F, 5, FALSE)) -> CORROSIF : Gants + lunettes obligatoires.
A42: Acide Citrique / حامض سيتريك | B42: 1.5 | C42: 1 | D42: =IF(AND(ISNUMBER(B42), ISNUMBER(C42)), B42*C42*$B$3, "") -> 12 | E42: =IF(A42="","",VLOOKUP(A42, Base_Donnees!A:F, 6, FALSE)) -> 410.55 | F42: =IF(ISNUMBER(D42), D42*E42, "") -> 4926.6 | G42: =IF(A42="","",IF(ISNUMBER(D42), IFERROR((D42/VLOOKUP(A42, Base_Donnees!A:F, 3, FALSE))*1000, "-"), "")) -> 20.338983 | H42: =IF(A42="","",VLOOKUP(A42, Base_Donnees!A:F, 4, FALSE)) -> 4 min | I42: =IF(A42="","",VLOOKUP(A42, Base_Donnees!A:F, 5, FALSE)) -> Idéal pour chélater et nettoyer les goutteurs.
E43: TOTAL FERTIGATION : | F43: =SUM(F10,F14,F15,F16,F20,F24,F29,F33,F37,F41,F42) -> 34672.4
A45: 🍃 PROGRAMME DE PULVÉRISATION FOLIAIRE & BIOSTIMULANTS
A46: Produit Sélectionné | B46: Dose Réf | C46: Hectares | D46: Dose Totale | E46: Prix Unitaire (DA) | F46: Coût Total | G46: Note Technique | H46: Cible
C47: =$B$3 -> 8 | D47: =IF(ISNUMBER(B47), B47*C47, "") | E47: =IF(A47="","",VLOOKUP(A47, Base_Donnees!A:F, 6, FALSE)) | F47: =IF(ISNUMBER(D47), D47*E47, "") | G47: =IF(A47="","",VLOOKUP(A47, Base_Donnees!A:F, 5, FALSE)) | H47: =IF(A47="","",VLOOKUP(A47, Base_Donnees!A:F, 4, FALSE))
C48: =$B$3 -> 8 | D48: =IF(ISNUMBER(B48), B48*C48, "") | E48: =IF(A48="","",VLOOKUP(A48, Base_Donnees!A:F, 6, FALSE)) | F48: =IF(ISNUMBER(D48), D48*E48, "") | G48: =IF(A48="","",VLOOKUP(A48, Base_Donnees!A:F, 5, FALSE)) | H48: =IF(A48="","",VLOOKUP(A48, Base_Donnees!A:F, 4, FALSE))
C49: =$B$3 -> 8 | D49: =IF(ISNUMBER(B49), B49*C49, "") | E49: =IF(A49="","",VLOOKUP(A49, Base_Donnees!A:F, 6, FALSE)) | F49: =IF(ISNUMBER(D49), D49*E49, "") | G49: =IF(A49="","",VLOOKUP(A49, Base_Donnees!A:F, 5, FALSE)) | H49: =IF(A49="","",VLOOKUP(A49, Base_Donnees!A:F, 4, FALSE))
E50: TOTAL PULVÉRISATION : | F50: =SUM(F47,F48,F49) -> 0
...

Sheet 01_Avril_Nectarine
A1: PROGRAMME DE PRÉCISION DOUBLE - NECTARINE : NABLARA et REDIX® 25
A3: NOMBRE D'HECTARES : | B3: 4
A4: DATE DU PROGRAMME : | B4: 2026-04-01
A5: ESPÈCE / PARCELLE : | B5: Nectarine : Nablara et REDIX® 25
A7: PROGRAMME 01
A8: 👉 RÈGLES DU BAC A : CUVES DU CALCIUM
A9: Produit (Réf Base) | B9: Dose / Ha / App | C9: Apps / Semaine | D9: Dose TOTALE Hebdo | E9: Prix Unitaire (DA) | F9: Montant Total Hebdo | G9: Eau Min (L) | H9: Temps dissolution | I9: Note Logistique
D10: =IF(AND(ISNUMBER(B10), ISNUMBER(C10)), B10*C10*$B$3, "") | E10: =IF(A10="","",VLOOKUP(A10, Base_Donnees!A:F, 6, FALSE)) | F10: =IF(ISNUMBER(D10), D10*E10, "") | G10: =IF(A10="","",IF(ISNUMBER(D10), IFERROR((D10/VLOOKUP(A10, Base_Donnees!A:F, 3, FALSE))*1000, "-"), "")) | H10: =IF(A10="","",VLOOKUP(A10, Base_Donnees!A:F, 4, FALSE)) | I10: =IF(A10="","",VLOOKUP(A10, Base_Donnees!A:F, 5, FALSE))
A12: 👉 RÈGLES DU BAC B : CUVE ÉNERGIE & MACRO-ÉLÉMENTS
A13: Produit (Réf Base) | B13: Dose / Ha / App | C13: Apps / Semaine | D13: Dose TOTALE Hebdo | E13: Prix Unitaire (DA) | F13: Montant Total Hebdo | G13: Eau Min (L) | H13: Temps dissolution | I13: Note Logistique
A14: Urée / يوريا | B14: 3 | C14: 2 | D14: =IF(AND(ISNUMBER(B14), ISNUMBER(C14)), B14*C14*$B$3, "") -> 24 | E14: =IF(A14="","",VLOOKUP(A14, Base_Donnees!A:F, 6, FALSE)) -> 45 | F14: =IF(ISNUMBER(D14), D14*E14, "") -> 1080 | G14: =IF(A14="","",IF(ISNUMBER(D14), IFERROR((D14/VLOOKUP(A14, Base_Donnees!A:F, 3, FALSE))*1000, "-"), "")) -> 228.57143 | H14: =IF(A14="","",VLOOKUP(A14, Base_Donnees!A:F, 4, FALSE)) -> 5 min | I14: =IF(A14="","",VLOOKUP(A14, Base_Donnees!A:F, 5, FALSE)) -> Très soluble. Refroidit l'eau (endothermique).
A15: Nitrate de Potassium / نترات البوتاسيوم | B15: 2.5 | C15: 2 | D15: =IF(AND(ISNUMBER(B15), ISNUMBER(C15)), B15*C15*$B$3, "") -> 20 | E15: =IF(A15="","",VLOOKUP(A15, Base_Donnees!A:F, 6, FALSE)) -> 26 | F15: =IF(ISNUMBER(D15), D15*E15, "") -> 520 | G15: =IF(A15="","",IF(ISNUMBER(D15), IFERROR((D15/VLOOKUP(A15, Base_Donnees!A:F, 3, FALSE))*1000, "-"), "")) -> 666.66667 | H15: =IF(A15="","",VLOOKUP(A15, Base_Donnees!A:F, 4, FALSE)) -> 15 min | I15: =IF(A15="","",VLOOKUP(A15, Base_Donnees!A:F, 5, FALSE)) -> Sensible à l'eau froide du puits.
A16: Nitrate de Magnésium / نترات ماغنسيوم | B16: 2.5 | C16: 2 | D16: =IF(AND(ISNUMBER(B16), ISNUMBER(C16)), B16*C16*$B$3, "") -> 20 | E16: =IF(A16="","",VLOOKUP(A16, Base_Donnees!A:F, 6, FALSE)) -> 260 | F16: =IF(ISNUMBER(D16), D16*E16, "") -> 5200 | G16: =IF(A16="","",IF(ISNUMBER(D16), IFERROR((D16/VLOOKUP(A16, Base_Donnees!A:F, 3, FALSE))*1000, "-"), "")) -> 285.71429 | H16: =IF(A16="","",VLOOKUP(A16, Base_Donnees!A:F, 4, FALSE)) -> 8 min | I16: =IF(A16="","",VLOOKUP(A16, Base_Donnees!A:F, 5, FALSE)) -> Excellente source de magnésium soluble.
A18: 👉 RÈGLES DU BAC C : OLIGO-ÉLÉMENTS, ACIDE HUMIQUE
A19: Produit (Réf Base) | B19: Dose / Ha / App | C19: Apps / Semaine | D19: Dose TOTALE Hebdo | E19: Prix Unitaire (DA) | F19: Montant Total Hebdo | G19: Eau Min (L) | H19: Temps dissolution | I19: Note Logistique
D20: =IF(AND(ISNUMBER(B20), ISNUMBER(C20)), B20*C20*$B$3, "") | E20: =IF(A20="","",VLOOKUP(A20, Base_Donnees!A:F, 6, FALSE)) | F20: =IF(ISNUMBER(D20), D20*E20, "") | G20: =IF(A20="","",IF(ISNUMBER(D20), IFERROR((D20/VLOOKUP(A20, Base_Donnees!A:F, 3, FALSE))*1000, "-"), "")) | H20: =IF(A20="","",VLOOKUP(A20, Base_Donnees!A:F, 4, FALSE)) | I20: =IF(A20="","",VLOOKUP(A20, Base_Donnees!A:F, 5, FALSE))
A22: 👉 RÈGLES DU BAC D (SÉPARÉ) : ACIDES DE NETTOYAGE
A23: Produit (Réf Base) | B23: Dose / Ha / App | C23: Apps / Semaine | D23: Dose TOTALE Hebdo | E23: Prix Unitaire (DA) | F23: Montant Total Hebdo | G23: Eau Min (L) | H23: Temps dissolution | I23: Note Logistique
A24: Acide Phosphorique / حامض فوسفوريك | B24: 2 | C24: 2 | D24: =IF(AND(ISNUMBER(B24), ISNUMBER(C24)), B24*C24*$B$3, "") -> 16 | E24: =IF(A24="","",VLOOKUP(A24, Base_Donnees!A:F, 6, FALSE)) -> 500 | F24: =IF(ISNUMBER(D24), D24*E24, "") -> 8000 | G24: =IF(A24="","",IF(ISNUMBER(D24), IFERROR((D24/VLOOKUP(A24, Base_Donnees!A:F, 3, FALSE))*1000, "-"), "")) -> 3.2 | H24: =IF(A24="","",VLOOKUP(A24, Base_Donnees!A:F, 4, FALSE)) -> 1 min | I24: =IF(A24="","",VLOOKUP(A24, Base_Donnees!A:F, 5, FALSE)) -> Sécurité : Toujours verser l'acide dans l'eau.
A26: PROGRAMME 02
A27: 👉 RÈGLES DU BAC A : CUVES DU CALCIUM
A28: Produit (Réf Base) | B28: Dose / Ha / App | C28: Apps / Semaine | D28: Dose TOTALE Hebdo | E28: Prix Unitaire (DA) | F28: Montant Total Hebdo | G28: Eau Min (L) | H28: Temps dissolution | I28: Note Logistique
A29: Nitrate de Calcium / نترات كالسـيوم | B29: 5 | C29: 1 | D29: =IF(AND(ISNUMBER(B29), ISNUMBER(C29)), B29*C29*$B$3, "") -> 20 | E29: =IF(A29="","",VLOOKUP(A29, Base_Donnees!A:F, 6, FALSE)) -> 160 | F29: =IF(ISNUMBER(D29), D29*E29, "") -> 3200 | G29: =IF(A29="","",IF(ISNUMBER(D29), IFERROR((D29/VLOOKUP(A29, Base_Donnees!A:F, 3, FALSE))*1000, "-"), "")) -> 166.66667 | H29: =IF(A29="","",VLOOKUP(A29, Base_Donnees!A:F, 4, FALSE)) -> 6 min | I29: =IF(A29="","",VLOOKUP(A29, Base_Donnees!A:F, 5, FALSE)) -> CRITIQUE : Isoler totalement des Sulfates/Phosphates.
A31: 👉 RÈGLES DU BAC B : CUVE ÉNERGIE & MACRO-ÉLÉMENTS
A32: Produit (Réf Base) | B32: Dose / Ha / App | C32: Apps / Semaine | D32: Dose TOTALE Hebdo | E32: Prix Unitaire (DA) | F32: Montant Total Hebdo | G32: Eau Min (L) | H32: Temps dissolution | I32: Note Logistique
D33: =IF(AND(ISNUMBER(B33), ISNUMBER(C33)), B33*C33*$B$3, "") | E33: =IF(A33="","",VLOOKUP(A33, Base_Donnees!A:F, 6, FALSE)) | F33: =IF(ISNUMBER(D33), D33*E33, "") | G33: =IF(A33="","",IF(ISNUMBER(D33), IFERROR((D33/VLOOKUP(A33, Base_Donnees!A:F, 3, FALSE))*1000, "-"), "")) | H33: =IF(A33="","",VLOOKUP(A33, Base_Donnees!A:F, 4, FALSE)) | I33: =IF(A33="","",VLOOKUP(A33, Base_Donnees!A:F, 5, FALSE))
A35: 👉 RÈGLES DU BAC C : OLIGO-ÉLÉMENTS, ACIDE HUMIQUE
A36: Produit (Réf Base) | B36: Dose / Ha / App | C36: Apps / Semaine | D36: Dose TOTALE Hebdo | E36: Prix Unitaire (DA) | F36: Montant Total Hebdo | G36: Eau Min (L) | H36: Temps dissolution | I36: Note Logistique
D37: =IF(AND(ISNUMBER(B37), ISNUMBER(C37)), B37*C37*$B$3, "") | E37: =IF(A37="","",VLOOKUP(A37, Base_Donnees!A:F, 6, FALSE)) | F37: =IF(ISNUMBER(D37), D37*E37, "") | G37: =IF(A37="","",IF(ISNUMBER(D37), IFERROR((D37/VLOOKUP(A37, Base_Donnees!A:F, 3, FALSE))*1000, "-"), "")) | H37: =IF(A37="","",VLOOKUP(A37, Base_Donnees!A:F, 4, FALSE)) | I37: =IF(A37="","",VLOOKUP(A37, Base_Donnees!A:F, 5, FALSE))
A39: 👉 RÈGLES DU BAC D (SÉPARÉ) : ACIDES DE NETTOYAGE
A40: Produit (Réf Base) | B40: Dose / Ha / App | C40: Apps / Semaine | D40: Dose TOTALE Hebdo | E40: Prix Unitaire (DA) | F40: Montant Total Hebdo | G40: Eau Min (L) | H40: Temps dissolution | I40: Note Logistique
A41: Acide Citrique / حامض سيتريك | B41: 2 | C41: 1 | D41: =IF(AND(ISNUMBER(B41), ISNUMBER(C41)), B41*C41*$B$3, "") -> 8 | E41: =IF(A41="","",VLOOKUP(A41, Base_Donnees!A:F, 6, FALSE)) -> 410.55 | F41: =IF(ISNUMBER(D41), D41*E41, "") -> 3284.4 | G41: =IF(A41="","",IF(ISNUMBER(D41), IFERROR((D41/VLOOKUP(A41, Base_Donnees!A:F, 3, FALSE))*1000, "-"), "")) -> 13.559322 | H41: =IF(A41="","",VLOOKUP(A41, Base_Donnees!A:F, 4, FALSE)) -> 4 min | I41: =IF(A41="","",VLOOKUP(A41, Base_Donnees!A:F, 5, FALSE)) -> Idéal pour chélater et nettoyer les goutteurs.
A42: Acide Nitrique / حامض نيتريك | B42: 1 | C42: 1 | D42: =IF(AND(ISNUMBER(B42), ISNUMBER(C42)), B42*C42*$B$3, "") -> 4 | E42: =IF(A42="","",VLOOKUP(A42, Base_Donnees!A:F, 6, FALSE)) -> 378.15 | F42: =IF(ISNUMBER(D42), D42*E42, "") -> 1512.6 | G42: =IF(A42="","",IF(ISNUMBER(D42), IFERROR((D42/VLOOKUP(A42, Base_Donnees!A:F, 3, FALSE))*1000, "-"), "")) -> 0.8 | H42: =IF(A42="","",VLOOKUP(A42, Base_Donnees!A:F, 4, FALSE)) -> 1 min | I42: =IF(A42="","",VLOOKUP(A42, Base_Donnees!A:F, 5, FALSE)) -> CORROSIF : Gants + lunettes obligatoires.
E44: TOTAL FERTIGATION : | F44: =SUM(F10,F14,F15,F16,F20,F24,F29,F33,F37,F41,F42) -> 22797
A46: 🍃 PROGRAMME DE PULVÉRISATION FOLIAIRE & BIOSTIMULANTS
A47: Produit Sélectionné | B47: Dose Réf | C47: Hectares | D47: Dose Totale | E47: Prix Unitaire (DA) | F47: Coût Total | G47: Note Technique | H47: Cible
A48: Algreen / طحالب بحرية | B48: 1.5 | C48: =$B$3 -> 4 | D48: =IF(ISNUMBER(B48), B48*C48, "") -> 6 | E48: =IF(A48="","",VLOOKUP(A48, Base_Donnees!A:F, 6, FALSE)) -> 2000 | F48: =IF(ISNUMBER(D48), D48*E48, "") -> 12000 | G48: =IF(A48="","",VLOOKUP(A48, Base_Donnees!A:F, 5, FALSE)) -> Soutien de la vigueur foliaire et division. | H48: =IF(A48="","",VLOOKUP(A48, Base_Donnees!A:F, 4, FALSE)) -> Extrait d'algues
A49: Oligo-éléments / عناصر صغري | B49: 1.5 | C49: =$B$3 -> 4 | D49: =IF(ISNUMBER(B49), B49*C49, "") -> 6 | E49: =IF(A49="","",VLOOKUP(A49, Base_Donnees!A:F, 6, FALSE)) -> 3450 | F49: =IF(ISNUMBER(D49), D49*E49, "") -> 20700 | G49: =IF(A49="","",VLOOKUP(A49, Base_Donnees!A:F, 5, FALSE)) -> Mélange complet d'oligo-éléments chélatés. | H49: =IF(A49="","",VLOOKUP(A49, Base_Donnees!A:F, 4, FALSE)) -> 10 min
C50: =$B$3 -> 4 | D50: =IF(ISNUMBER(B50), B50*C50, "") | E50: =IF(A50="","",VLOOKUP(A50, Base_Donnees!A:F, 6, FALSE)) | F50: =IF(ISNUMBER(D50), D50*E50, "") | G50: =IF(A50="","",VLOOKUP(A50, Base_Donnees!A:F, 5, FALSE)) | H50: =IF(A50="","",VLOOKUP(A50, Base_Donnees!A:F, 4, FALSE))
E51: TOTAL PULVÉRISATION : | F51: =SUM(F48,F49,F50) -> 32700
...

Sheet 01_Avril_Pommier
A1: PROGRAMME DE PRÉCISION DOUBLE - POMMIER : POMMIER 1
A3: NOMBRE D'HECTARES : | B3: 2
A4: DATE DU PROGRAMME : | B4: 2026-04-01
A5: ESPÈCE / PARCELLE : | B5: Pommier : Pommier 1 et 2
A7: PROGRAMME 01
A8: 👉 RÈGLES DU BAC A : CUVES DU CALCIUM
A9: Produit (Réf Base) | B9: Dose / Ha / App | C9: Apps / Semaine | D9: Dose TOTALE Hebdo | E9: Prix Unitaire (DA) | F9: Montant Total Hebdo | G9: Eau Min (L) | H9: Temps dissolution | I9: Note Logistique
D10: =IF(AND(ISNUMBER(B10), ISNUMBER(C10)), B10*C10*$B$3, "") | E10: =IF(A10="","",VLOOKUP(A10, Base_Donnees!A:F, 6, FALSE)) | F10: =IF(ISNUMBER(D10), D10*E10, "") | G10: =IF(A10="","",IF(ISNUMBER(D10), IFERROR((D10/VLOOKUP(A10, Base_Donnees!A:F, 3, FALSE))*1000, "-"), "")) | H10: =IF(A10="","",VLOOKUP(A10, Base_Donnees!A:F, 4, FALSE)) | I10: =IF(A10="","",VLOOKUP(A10, Base_Donnees!A:F, 5, FALSE))
A12: 👉 RÈGLES DU BAC B : CUVE ÉNERGIE & MACRO-ÉLÉMENTS
A13: Produit (Réf Base) | B13: Dose / Ha / App | C13: Apps / Semaine | D13: Dose TOTALE Hebdo | E13: Prix Unitaire (DA) | F13: Montant Total Hebdo | G13: Eau Min (L) | H13: Temps dissolution | I13: Note Logistique
A14: Urée / يوريا | B14: 2.5 | C14: 2 | D14: =IF(AND(ISNUMBER(B14), ISNUMBER(C14)), B14*C14*$B$3, "") -> 10 | E14: =IF(A14="","",VLOOKUP(A14, Base_Donnees!A:F, 6, FALSE)) -> 45 | F14: =IF(ISNUMBER(D14), D14*E14, "") -> 450 | G14: =IF(A14="","",IF(ISNUMBER(D14), IFERROR((D14/VLOOKUP(A14, Base_Donnees!A:F, 3, FALSE))*1000, "-"), "")) -> 95.238095 | H14: =IF(A14="","",VLOOKUP(A14, Base_Donnees!A:F, 4, FALSE)) -> 5 min | I14: =IF(A14="","",VLOOKUP(A14, Base_Donnees!A:F, 5, FALSE)) -> Très soluble. Refroidit l'eau (endothermique).
A15: Sulfate de Potassium / سلفات البوتاسيوم SOP | B15: 2.5 | C15: 2 | D15: =IF(AND(ISNUMBER(B15), ISNUMBER(C15)), B15*C15*$B$3, "") -> 10 | E15: =IF(A15="","",VLOOKUP(A15, Base_Donnees!A:F, 6, FALSE)) -> 220 | F15: =IF(ISNUMBER(D15), D15*E15, "") -> 2200 | G15: =IF(A15="","",IF(ISNUMBER(D15), IFERROR((D15/VLOOKUP(A15, Base_Donnees!A:F, 3, FALSE))*1000, "-"), "")) -> 1000 | H15: =IF(A15="","",VLOOKUP(A15, Base_Donnees!A:F, 4, FALSE)) -> 20 min | I15: =IF(A15="","",VLOOKUP(A15, Base_Donnees!A:F, 5, FALSE)) -> Le plus difficile à dissoudre du marché.
A16: Nitrate de Magnésium / نترات ماغنسيوم | B16: 1.5 | C16: 2 | D16: =IF(AND(ISNUMBER(B16), ISNUMBER(C16)), B16*C16*$B$3, "") -> 6 | E16: =IF(A16="","",VLOOKUP(A16, Base_Donnees!A:F, 6, FALSE)) -> 260 | F16: =IF(ISNUMBER(D16), D16*E16, "") -> 1560 | G16: =IF(A16="","",IF(ISNUMBER(D16), IFERROR((D16/VLOOKUP(A16, Base_Donnees!A:F, 3, FALSE))*1000, "-"), "")) -> 85.714286 | H16: =IF(A16="","",VLOOKUP(A16, Base_Donnees!A:F, 4, FALSE)) -> 8 min | I16: =IF(A16="","",VLOOKUP(A16, Base_Donnees!A:F, 5, FALSE)) -> Excellente source de magnésium soluble.
A18: 👉 RÈGLES DU BAC C : OLIGO-ÉLÉMENTS, ACIDE HUMIQUE
A19: Produit (Réf Base) | B19: Dose / Ha / App | C19: Apps / Semaine | D19: Dose TOTALE Hebdo | E19: Prix Unitaire (DA) | F19: Montant Total Hebdo | G19: Eau Min (L) | H19: Temps dissolution | I19: Note Logistique
D20: =IF(AND(ISNUMBER(B20), ISNUMBER(C20)), B20*C20*$B$3, "") | E20: =IF(A20="","",VLOOKUP(A20, Base_Donnees!A:F, 6, FALSE)) | F20: =IF(ISNUMBER(D20), D20*E20, "") | G20: =IF(A20="","",IF(ISNUMBER(D20), IFERROR((D20/VLOOKUP(A20, Base_Donnees!A:F, 3, FALSE))*1000, "-"), "")) | H20: =IF(A20="","",VLOOKUP(A20, Base_Donnees!A:F, 4, FALSE)) | I20: =IF(A20="","",VLOOKUP(A20, Base_Donnees!A:F, 5, FALSE))
A22: 👉 RÈGLES DU BAC D (SÉPARÉ) : ACIDES DE NETTOYAGE
A23: Produit (Réf Base) | B23: Dose / Ha / App | C23: Apps / Semaine | D23: Dose TOTALE Hebdo | E23: Prix Unitaire (DA) | F23: Montant Total Hebdo | G23: Eau Min (L) | H23: Temps dissolution | I23: Note Logistique
A24: Acide Phosphorique / حامض فوسفوريك | B24: 2.5 | C24: 2 | D24: =IF(AND(ISNUMBER(B24), ISNUMBER(C24)), B24*C24*$B$3, "") -> 10 | E24: =IF(A24="","",VLOOKUP(A24, Base_Donnees!A:F, 6, FALSE)) -> 500 | F24: =IF(ISNUMBER(D24), D24*E24, "") -> 5000 | G24: =IF(A24="","",IF(ISNUMBER(D24), IFERROR((D24/VLOOKUP(A24, Base_Donnees!A:F, 3, FALSE))*1000, "-"), "")) -> 2 | H24: =IF(A24="","",VLOOKUP(A24, Base_Donnees!A:F, 4, FALSE)) -> 1 min | I24: =IF(A24="","",VLOOKUP(A24, Base_Donnees!A:F, 5, FALSE)) -> Sécurité : Toujours verser l'acide dans l'eau.
A26: PROGRAMME 02
A27: 👉 RÈGLES DU BAC A : CUVES DU CALCIUM
A28: Produit (Réf Base) | B28: Dose / Ha / App | C28: Apps / Semaine | D28: Dose TOTALE Hebdo | E28: Prix Unitaire (DA) | F28: Montant Total Hebdo | G28: Eau Min (L) | H28: Temps dissolution | I28: Note Logistique
A29: Nitrate de Calcium / نترات كالسـيوم | B29: 5 | C29: 1 | D29: =IF(AND(ISNUMBER(B29), ISNUMBER(C29)), B29*C29*$B$3, "") -> 10 | E29: =IF(A29="","",VLOOKUP(A29, Base_Donnees!A:F, 6, FALSE)) -> 160 | F29: =IF(ISNUMBER(D29), D29*E29, "") -> 1600 | G29: =IF(A29="","",IF(ISNUMBER(D29), IFERROR((D29/VLOOKUP(A29, Base_Donnees!A:F, 3, FALSE))*1000, "-"), "")) -> 83.333333 | H29: =IF(A29="","",VLOOKUP(A29, Base_Donnees!A:F, 4, FALSE)) -> 6 min | I29: =IF(A29="","",VLOOKUP(A29, Base_Donnees!A:F, 5, FALSE)) -> CRITIQUE : Isoler totalement des Sulfates/Phosphates.
A31: 👉 RÈGLES DU BAC B : CUVE ÉNERGIE & MACRO-ÉLÉMENTS
A32: Produit (Réf Base) | B32: Dose / Ha / App | C32: Apps / Semaine | D32: Dose TOTALE Hebdo | E32: Prix Unitaire (DA) | F32: Montant Total Hebdo | G32: Eau Min (L) | H32: Temps dissolution | I32: Note Logistique
D33: =IF(AND(ISNUMBER(B33), ISNUMBER(C33)), B33*C33*$B$3, "") | E33: =IF(A33="","",VLOOKUP(A33, Base_Donnees!A:F, 6, FALSE)) | F33: =IF(ISNUMBER(D33), D33*E33, "") | G33: =IF(A33="","",IF(ISNUMBER(D33), IFERROR((D33/VLOOKUP(A33, Base_Donnees!A:F, 3, FALSE))*1000, "-"), "")) | H33: =IF(A33="","",VLOOKUP(A33, Base_Donnees!A:F, 4, FALSE)) | I33: =IF(A33="","",VLOOKUP(A33, Base_Donnees!A:F, 5, FALSE))
A35: 👉 RÈGLES DU BAC C : OLIGO-ÉLÉMENTS, ACIDE HUMIQUE
A36: Produit (Réf Base) | B36: Dose / Ha / App | C36: Apps / Semaine | D36: Dose TOTALE Hebdo | E36: Prix Unitaire (DA) | F36: Montant Total Hebdo | G36: Eau Min (L) | H36: Temps dissolution | I36: Note Logistique
D37: =IF(AND(ISNUMBER(B37), ISNUMBER(C37)), B37*C37*$B$3, "") | E37: =IF(A37="","",VLOOKUP(A37, Base_Donnees!A:F, 6, FALSE)) | F37: =IF(ISNUMBER(D37), D37*E37, "") | G37: =IF(A37="","",IF(ISNUMBER(D37), IFERROR((D37/VLOOKUP(A37, Base_Donnees!A:F, 3, FALSE))*1000, "-"), "")) | H37: =IF(A37="","",VLOOKUP(A37, Base_Donnees!A:F, 4, FALSE)) | I37: =IF(A37="","",VLOOKUP(A37, Base_Donnees!A:F, 5, FALSE))
A39: 👉 RÈGLES DU BAC D (SÉPARÉ) : ACIDES DE NETTOYAGE
A40: Produit (Réf Base) | B40: Dose / Ha / App | C40: Apps / Semaine | D40: Dose TOTALE Hebdo | E40: Prix Unitaire (DA) | F40: Montant Total Hebdo | G40: Eau Min (L) | H40: Temps dissolution | I40: Note Logistique
A41: Acide Citrique / حامض سيتريك | B41: 2 | C41: 1 | D41: =IF(AND(ISNUMBER(B41), ISNUMBER(C41)), B41*C41*$B$3, "") -> 4 | E41: =IF(A41="","",VLOOKUP(A41, Base_Donnees!A:F, 6, FALSE)) -> 410.55 | F41: =IF(ISNUMBER(D41), D41*E41, "") -> 1642.2 | G41: =IF(A41="","",IF(ISNUMBER(D41), IFERROR((D41/VLOOKUP(A41, Base_Donnees!A:F, 3, FALSE))*1000, "-"), "")) -> 6.779661 | H41: =IF(A41="","",VLOOKUP(A41, Base_Donnees!A:F, 4, FALSE)) -> 4 min | I41: =IF(A41="","",VLOOKUP(A41, Base_Donnees!A:F, 5, FALSE)) -> Idéal pour chélater et nettoyer les goutteurs.
A42: Acide Nitrique / حامض نيتريك | B42: 1 | C42: 1 | D42: =IF(AND(ISNUMBER(B42), ISNUMBER(C42)), B42*C42*$B$3, "") -> 2 | E42: =IF(A42="","",VLOOKUP(A42, Base_Donnees!A:F, 6, FALSE)) -> 378.15 | F42: =IF(ISNUMBER(D42), D42*E42, "") -> 756.3 | G42: =IF(A42="","",IF(ISNUMBER(D42), IFERROR((D42/VLOOKUP(A42, Base_Donnees!A:F, 3, FALSE))*1000, "-"), "")) -> 0.4 | H42: =IF(A42="","",VLOOKUP(A42, Base_Donnees!A:F, 4, FALSE)) -> 1 min | I42: =IF(A42="","",VLOOKUP(A42, Base_Donnees!A:F, 5, FALSE)) -> CORROSIF : Gants + lunettes obligatoires.
E44: TOTAL FERTIGATION : | F44: =SUM(F10,F14,F15,F16,F20,F24,F29,F33,F37,F41,F42) -> 13208.5
A46: 🍃 PROGRAMME DE PULVÉRISATION FOLIAIRE & BIOSTIMULANTS
A47: Produit Sélectionné | B47: Dose Réf | C47: Hectares | D47: Dose Totale | E47: Prix Unitaire (DA) | F47: Coût Total | G47: Note Technique | H47: Cible
A48: Cytokinine / سيتوكينين | B48: 1 | C48: =$B$3 -> 2 | D48: =IF(ISNUMBER(B48), B48*C48, "") -> 2 | E48: =IF(A48="","",VLOOKUP(A48, Base_Donnees!A:F, 6, FALSE)) -> 2500 | F48: =IF(ISNUMBER(D48), D48*E48, "") -> 5000 | G48: =IF(A48="","",VLOOKUP(A48, Base_Donnees!A:F, 5, FALSE)) -> Division cellulaire | H48: =IF(A48="","",VLOOKUP(A48, Base_Donnees!A:F, 4, FALSE)) -> Hormone
A49: Calcium-Bore Foliaire / كالسيوم بورون | B49: 1.5 | C49: =$B$3 -> 2 | D49: =IF(ISNUMBER(B49), B49*C49, "") -> 3 | E49: =IF(A49="","",VLOOKUP(A49, Base_Donnees!A:F, 6, FALSE)) -> 550 | F49: =IF(ISNUMBER(D49), D49*E49, "") -> 1650 | G49: =IF(A49="","",VLOOKUP(A49, Base_Donnees!A:F, 5, FALSE)) -> Appliquer aux stades critiques du fruit. | H49: =IF(A49="","",VLOOKUP(A49, Base_Donnees!A:F, 4, FALSE)) -> Fermeté fruit
C50: =$B$3 -> 2 | D50: =IF(ISNUMBER(B50), B50*C50, "") | E50: =IF(A50="","",VLOOKUP(A50, Base_Donnees!A:F, 6, FALSE)) | F50: =IF(ISNUMBER(D50), D50*E50, "") | G50: =IF(A50="","",VLOOKUP(A50, Base_Donnees!A:F, 5, FALSE)) | H50: =IF(A50="","",VLOOKUP(A50, Base_Donnees!A:F, 4, FALSE))
E51: TOTAL PULVÉRISATION : | F51: =SUM(F48,F49,F50) -> 6650
...

Sheet 20_Avril_Nectarine
A1: PROGRAMME DE PRÉCISION DOUBLE - NECTARINE : NABARA
A3: NOMBRE D'HECTARES : | B3: 4
A4: DATE DU PROGRAMME : | B4: 2026-04-20
A5: ESPÈCE / PARCELLE : | B5: Nectarine : Nabara
A7: PROGRAMME 01
A8: 👉 RÈGLES DU BAC A : CUVES DU CALCIUM
A9: Produit (Réf Base) | B9: Dose / Ha / App | C9: Apps / Semaine | D9: Dose TOTALE Hebdo | E9: Prix Unitaire (DA) | F9: Montant Total Hebdo | G9: Eau Min (L) | H9: Temps dissolution | I9: Note Logistique
